Workbook

Sheet 4TA
A1: JUGADOR | B1: DNI | C1: 2024 | D1: 45679 | E1: 45686 | F1: 45728 | G1: 45735 | H1: 45749 | I1: 45756 | J1: 45763 | K1: 45770 | L1: 45777 | M1: 45784 | N1: 45791 | O1: 45798 | P1: 45805 | Q1: 45812 | R1: 45819 | S1: 45826 | T1: 45849 | U1: 45861 | V1: 45868 | W1: 45875 | X1: 45882 | Y1: 45889 | Z1: 45896 | AA1: 45903 | AB1: 45910 | AC1: 45917 | AD1: PAUTAS | AE1: DIFERENCIA sem | AF1: DIFERENCIA ANUAL
A2: ALAYO IARLEY | B2: 72079419 | C2: 68.9 | D2: 68.5 | E2: 69.4 | F2: 68.9 | G2: 69 | I2: 71.4 | J2: 72.2 | L2: 69.9 | N2: 71.7 | O2: 71.8 | U2: 70.5 | W2: 70.9 | X2: 71.7 | Z2: 71.3 | AA2: 71.4 | AB2: 71.5 | AC2: 71.3 | AD2: DESCENSO | AE2: =AC2-AB2 -> -0.2 | AF2: =AA2-C2 -> 2.5
A3: BIMA SANTINO | B3: 46660924 | C3: 78.8 | F3: 76.7 | AD3: RESERVA | AE3: =AC3-AB3 -> 0 | AF3: =AA3-C3 -> -78.8
A4: BURGOS TORRES MAXIMO | B4: 46265094 | D4: 62.4 | E4: 62.3 | F4: 61.9 | G4: 62 | I4: 61.4 | J4: 62 | M4: 61.9 | N4: 62 | O4: 62.2 | P4: 61.4 | Q4: 62 | R4: 62.3 | S4: 62 | T4: 61.7 | W4: 63.2 | AE4: =AC4-AB4 -> 0 | AF4: =AA4-D4 -> -62.4
A5: CACERES THIAGO | B5: 47388944 | C5: 76.7 | E5: 76 | F5: 77.3 | G5: 77.7 | H5: 77.9 | J5: 78.9 | K5: 77.9 | L5: 77.9 | O5: 76.6 | R5: 77.4 | S5: 77.8 | V5: 77.9 | W5: 78 | X5: 78.2 | Y5: 78.2 | AA5: 78.2 | AB5: 78.4 | AD5: RESERVA | AE5: =AC5-AB5 -> -78.4 | AF5: =AA5-C5 -> 1.5
A6: CORSARO IAN | B6: 47396035 | E6: 70.9 | F6: 70.8 | G6: 71.7 | H6: 72.1 | I6: 71.1 | J6: 72.9 | L6: 72.1 | M6: 72.3 | N6: 72.7 | O6: 72.7 | P6: 73.5 | Q6: 74 | R6: 73.7 | S6: 74.4 | T6: 75 | U6: 73.8 | V6: 73.4 | W6: 74.1 | X6: 73.7 | Y6: 73.7 | AD6: MANTENIMIENTO | AE6: =AC6-AB6 -> 0 | AF6: =AA6-E6 -> -70.9
A7: GIMENEZ MATIAS | B7: 47223356 | C7: - | D7: 64.1 | E7: 64.1 | F7: 62.6 | G7: 61.9 | H7: 61.1 | I7: 61.8 | J7: 62.4 | L7: 61.9 | M7: 60.6 | N7: 61 | O7: 61.8 | P7: 62.1 | Q7: 61.9 | R7: 63.1 | S7: 62.7 | T7: 62.8 | U7: 63 | V7: 63 | W7: 62.7 | X7: 63.2 | Y7: 63.5 | Z7: 63.5 | AA7: 63.1 | AB7: 63 | AC7: 62.9 | AD7: AUMENTO | AE7: =AC7-AB7 -> -0.1 | AF7: =AA7-D7 -> -1
A8: IDARRAGA JUAN | B8: 1013108875 | C8: 70.2 | D8: 70 | E8: 69.9 | F8: 71.4 | G8: 71.4 | I8: 71.8 | J8: 72.5 | K8: 73 | M8: 71.7 | N8: 72.8 | O8: 72.6 | P8: 72.6 | Q8: 73 | R8: 72.8 | S8: 72.7 | T8: 73.3 | V8: 72.5 | W8: 74 | Y8: 78.2 | AA8: 73 | AB8: 73.2 | AC8: 72.5 | AD8: MANTENIMIENTO | AE8: =AC8-AB8 -> -0.7 | AF8: =AA8-C8 -> 2.8
A9: KALIGER IGNACIO | B9: 47302245 | C9: 63.5 | D9: 64.8 | E9: 63.5 | J9: 65.1 | K9: 65.9 | L9: 65.7 | N9: 66.2 | O9: 65.5 | P9: 66.7 | Q9: 67 | R9: 66.2 | S9: 66.5 | T9: 68 | U9: 67.3 | V9: 67.6 | W9: 67.7 | X9: 67.4 | Y9: 68.5 | Z9: 67.4 | AA9: 67.6 | AB9: 66.7 | AC9: 66.8 | AD9: MANTENIMIENTO | AE9: =AC9-AB9 -> 0.1 | AF9: =AA9-C9 -> 4.1
A10: LUCIANI | B10: 47396035 | D10: 79.8 | E10: 78.6 | F10: 77.5 | G10: 78.1 | H10: 76.4 | I10: 76.6 | J10: 76.2 | K10: 76.5 | L10: 76.8 | M10: 76.8 | N10: 76.3 | O10: 76.5 | P10: 75.9 | Q10: 76 | R10: 76.1 | S10: 76 | U10: 77.4 | V10: 76.9 | W10: 76.8 | X10: 77.3 | Y10: 77.4 | Z10: 76.8 | AA10: 77.7 | AB10: 77.2 | AC10: 76.8 | AD10: DESCENSO RESERVA | AE10: =AC10-AB10 -> -0.4 | AF10: =AA10-D10 -> -2.1
A11: LUGO LOPEZ ERNESTO | B11: 46153639 | C11: 83.9 | D11: 83.5 | E11: 82.5 | F11: 83.7 | G11: 83.9 | L11: 83.2 | U11: 83.8 | V11: 83.5 | X11: 82.9 | Y11: R | AE11: =AC11-AB11 -> 0 | AF11: =AA11-C11 -> -83.9
A12: MARTÍNEZ OSCAR | B12: 46418718 | V12: 72.1 | W12: 73.8 | Y12: 73 | Z12: 72.8 | AA12: 73.5 | AB12: 72.3 | AC12: 72.5 | AE12: =AC12-AB12 -> 0.2 | AF12: =AA12-V12 -> 1.4
A13: MORA LAUTARO | B13: 46503125 | F13: 74.1 | J13: 84.4 | AD13: RESERVA | AE13: =AC13-AB13 -> 0 | AF13: =AA13-F13 -> -74.1
A14: ORTIZ LUCAS | B14: 47388493 | C14: 64.3 | D14: 65.6 | E14: 64.5 | F14: 63.6 | G14: 64.3 | H14: 63.7 | J14: 63.1 | L14: 64.1 | M14: 63 | N14: 64.2 | O14: 63.5 | Q14: 64 | S14: 64.4 | U14: 63.4 | V14: 64.4 | X14: 63.8 | Y14: 62.8 | Z14: 64.3 | AB14: 64.6 | AC14: 63.9 | AD14: AUMENTO | AE14: =AC14-AB14 -> -0.7 | AF14: =AA14-C14 -> -64.3
A15: POZA ADRIEL | B15: 45687569 | C15: 76.4 | D15: 74.8 | E15: 75.2 | F15: 74.7 | G15: 74.8 | H15: 75.2 | J15: 74.7 | L15: 74.3 | M15: 74.2 | N15: 74.6 | O15: 74.2 | P15: 74.3 | Q15: 73.6 | R15: 74 | S15: 74.3 | T15: 73.6 | U15: 74.1 | V15: 74.4 | Y15: 74.4 | Z15: 74.7 | AA15: 74.9 | AB15: 75 | AC15: 74.5 | AD15: DESCENSO | AE15: =AC15-AB15 -> -0.5 | AF15: =AA15-C15 -> -1.5
A16: RIEGEL MARIANO | B16: 47535569 | C16: 64.5 | D16: 66.1 | F16: 65.8 | G16: 66.1 | J16: 66.7 | L16: 66.5 | M16: 66.5 | N16: 66.4 | O16: 66.3 | S16: 67.1 | U16: 67.4 | V16: 67.8 | X16: 67.9 | Y16: 67.9 | Z16: 67.5 | AB16: 67.1 | AC16: 67 | AD16: MANTENIMIENTO | AE16: =AC16-AB16 -> -0.1 | AF16: =AA16-C16 -> -64.5
A17: SAMBADE JOAQUIN | B17: 47573081 | C17: 75.2 | E17: 74.5 | F17: 72.6 | J17: 73.5 | L17: 73.6 | N17: 73.7 | O17: 73 | P17: 74.4 | Q17: 75.2 | R17: 75.2 | S17: 74.9 | U17: 77.1 | V17: 76 | W17: 76.8 | X17: 78.2 | Y17: 77.6 | Z17: 77.9 | AA17: 78 | AB17: 78 | AC17: 78.2 | AE17: =AC17-AB17 -> 0.2 | AF17: =AA17-C17 -> 2.8
A18: SANCHEZ FACUNDO (R) | B18: 47276825 | C18: 70 | E18: 71 | F18: 71.1 | G18: 71.9 | J18: 72.4 | K18: 71.7 | M18: 71.7 | Q18: 72.1 | R18: 72.1 | T18: 73.6 | U18: 71.6 | V18: 72.4 | W18: 72.3 | X18: 71.8 | Y18: 72.8 | Z18: 72.1 | AA18: 73.6 | AB18: 72.7 | AC18: 73.2 | AD18: MANTENIMIENTO | AE18: =AC18-AB18 -> 0.5 | AF18: =AA18-C18 -> 3.6
A19: SEGOVIA SANTIAGO | B19: 45684467 | F19: 69.5 | G19: 70.4 | J19: 70.5 | K19: 70.2 | L19: 70.9 | M19: 70.6 | N19: 70.6 | O19: 69.7 | P19: 70.3 | Q19: 71.1 | R19: 70.1 | S19: 70.2 | T19: 70 | W19: 71.3 | X19: 71.7 | Y19: 71.5 | Z19: 71.3 | AE19: =AC19-AB19 -> 0 | AF19: =AA19-F19 -> -69.5
A20: COSCIO IGNACIO | B20: 47403526 | AB20: 86.8 | AC20: 86 | AE20: =AC20-AB20 -> -0.8
A21: ERLINCH JOEL | B21: 47176715 | C21: 83.4 | D21: 86.9 | E21: 86.2 | F21: 83.1 | G21: 84.1 | H21: 84.1 | J21: 84 | K21: 84.7 | L21: 82.8 | M21: 85.8 | N21: 83.4 | O21: 84.6 | P21: 85.2 | AE21: =AC21-AB21 -> 0
A22: GRICENIUK TOBIAS | B22: 46979050 | C22: 83 | D22: 83.2 | E22: 84.6 | AE22: =AC22-AB22 -> 0
A23: JULIAN JUAN CRUZ | B23: 47793015 | C23: 75.4 | D23: 75.4 | AE23: =AC23-AB23 -> 0
A24: SARZINSKY TOMAS (R) | B24: 46582780 | C24: 63.8 | F24: 67.2 | H24: 70.8 | AE24: =AC24-AB24 -> 0
A25: BOURQUIN JUAN IGNACIO | B25: 46329651 | C25: 85.2 | D25: 85.8 | E25: 85.7 | H25: 82 | J25: 84.4 | AB25: 84.1 | AC25: 83.9 | AE25: =AC25-AB25 -> -0.2
A26: COSTA LUCAS | B26: 52219585 | C26: 76.3 | D26: 76.8 | E26: 77.5 | F26: 77.9 | G26: 79.1 | H26: 77.3 | I26: 77.2 | K26: 77.7 | L26: 76.7 | M26: 78.1 | N26: 79 | O26: 79.1 | P26: 79.7 | Q26: 80 | R26: 79.8 | S26: 81.5 | AE26: =AC26-AB26 -> 0
A27: GARCIA PATRICIO ALAN | C27: 71.1 | D27: 71.7 | E27: 71.4 | F27: 71.5 | G27: 72.4 | H27: 72.1 | I27: 72.9 | J27: 71.9 | L27: 73.1 | N27: 73.1 | P27: 74 | Q27: 73.9 | S27: 74.2 | T27: 73.7 | AE27: =AC27-AB27 -> 0

Sheet 5TA (07)
A1: CAH - 5ta div -25
A2: JUGADOR | B2: 2024 | C2: 45679 | D2: 45686 | E2: 45693 | F2: 45728 | G2: 45735 | H2: 45749 | I2: 45756 | J2: 45763 | K2: 45770 | L2: 45777 | M2: 45784 | N2: 45791 | O2: 45798 | P2: 45805 | Q2: 45812 | R2: 45819 | S2: 45826 | T2: 45849 | U2: 45861 | V2: 45868 | W2: 45875 | X2: 45882 | Y2: 45889 | Z2: 45896 | AA2: 45903 | AB2: 45910 | AC2: 45917 | AD2: PAUTAS | AE2: DIFERENCIA sem | AF2: DIFERENCIA ANUAL
A3: ACEVEDO THIAGO | C3: 68.7 | D3: 68.1 | E3: 71 | F3: 71.2 | G3: 73.2 | H3: 72.6 | I3: 73 | J3: 73.4 | K3: 74.1 | L3: 73.4 | M3: 74.4 | N3: 73.7 | O3: 74.7 | P3: 73.2 | Q3: 73.9 | R3: 74.2 | S3: 74.5 | U3: 73.8 | V3: 75.3 | W3: 73.6 | X3: 74.7 | Y3: 74.3 | Z3: 75.5 | AA3: 75 | AB3: 75.4 | AC3: 75.5 | AD3: MANTENIMIENTO | AE3: =AC3-AB3 -> 0.1 | AF3: =AA3-C3 -> 6.3
A4: ARANDA TOBIAS | B4: 68.1 | F4: 68.2 | M4: 69.4 | R4: 69.7 | S4: 69.7 | U4: 69.2 | V4: 69.4 | W4: 70.1 | X4: 69.8 | Y4: 70.4 | Z4: 71 | AA4: 70.6 | AB4: 70.6 | AC4: 70.8 | AD4: RESERVA | AE4: =AC4-AB4 -> 0.2 | AF4: =AA4-B4 -> 2.5
A5: BAEZ ELIAN | B5: 72.3 | C5: 71.6 | D5: 70.2 | E5: 69.8 | F5: 71.5 | G5: 71.5 | H5: 71.4 | I5: 72.9 | J5: 70.1 | K5: 71.6 | L5: 71.9 | M5: 71.6 | N5: 72.5 | O5: 70.9 | P5: 71.8 | Q5: 71.5 | R5: 72.9 | S5: 72.3 | U5: 72.4 | V5: 73.3 | W5: 73.2 | X5: 73 | Y5: 71.7 | Z5: 71.7 | AC5: 73.9 | AD5: MANTENIMIENTO | AE5: =AC5-AB5 -> 73.9 | AF5: =AA5-B5 -> -72.3
A6: BENITEZ JOAQUIN | B6: 70.9 | C6: 68.6 | D6: 69.6 | G6: 69.5 | H6: 69 | I6: 70 | J6: 69.6 | K6: 69.6 | L6: 69.3 | M6: 70.3 | N6: 70.5 | P6: 71.9 | Q6: 70.4 | R6: 70.5 | S6: 70.9 | U6: 70.9 | V6: 70.2 | W6: 70.3 | X6: 70 | Y6: 70.4 | Z6: 71.1 | AA6: 70.9 | AB6: 71.3 | AC6: 69.8 | AD6: MANTENIMIENTO | AE6: =AC6-AB6 -> -1.5 | AF6: =AA6-B6 -> 0
A7: BOGADO LAUTARO | F7: 61.9 | I7: 62.3 | P7: RESER | R7: 62.4 | U7: 64 | W7: 64.5 | Z7: 63.7 | AA7: 64.1 | AB7: 64.3 | AC7: 64.7 | AD7: RESERVA | AE7: =AC7-AB7 -> 0.4 | AF7: =AA7-F7 -> 2.2
A8: CARRO BAUTISTA | B8: 74.6 | E8: 74.1 | G8: 73.9 | I8: 74.9 | L8: 74.6 | M8: 74.2 | O8: 76.7 | Q8: 75.8 | R8: 76.1 | S8: 77 | U8: 76.4 | V8: 76 | W8: 77.1 | X8: 76.6 | Y8: 76.6 | Z8: 76.5 | AA8: 76.8 | AB8: 75.4 | AC8: 75.7 | AD8: DESCENSO | AE8: =AC8-AB8 -> 0.3 | AF8: =AA8-B8 -> 2.2
A9: CASTELLANOS MARTIN | B9: 65.5 | C9: 65 | D9: 64.8 | E9: 67 | G9: 67.7 | H9: 69.3 | I9: 69.2 | J9: 69.5 | K9: 69.7 | L9: 69 | M9: 69.8 | N9: 69 | O9: 70.2 | P9: 69.9 | Q9: 69.4 | R9: 70.1 | S9: 70 | U9: 70.2 | V9: 69.5 | W9: 70.2 | X9: 69.8 | Y9: 70.2 | Z9: 70.7 | AA9: 70 | AB9: 71.7 | AC9: 70.8 | AD9: DESCENSO | AE9: =AC9-AB9 -> -0.9 | AF9: =AA9-B9 -> 4.5
A10: CATRIEL GERONIMO | D10: 68.5 | E10: 68.5 | F10: 69 | G10: 69.2 | H10: 68.9 | I10: 69.3 | M10: 70.2 | N10: 70.9 | O10: 70.9 | P10: 70.8 | Q10: 70.6 | R10: 69.9 | S10: 71 | T10: 71.6 | U10: 71.3 | V10: 71.1 | W10: 71.1 | X10: 70.6 | Y10: 70.5 | Z10: 71.8 | AA10: 71.4 | AB10: 70.8 | AC10: 71.4 | AD10: DESCENSO | AE10: =AC10-AB10 -> 0.6 | AF10: =AA10-D10 -> 2.9
A11: CHIQUICHANO MATIAS | D11: 80.6 | E11: 80 | F11: 80.7 | G11: 79.4 | H11: 79 | I11: 80.7 | J11: 79.3 | K11: 79.7 | L11: 78.6 | M11: 78.8 | N11: 78.5 | O11: 78.5 | P11: 77.9 | Q11: 80.4 | R11: 79.7 | S11: 78.7 | U11: 79.4 | V11: 80 | W11: 79.1 | X11: 79.8 | Y11: 79.8 | Z11: 80.3 | AA11: 79.3 | AB11: 80.2 | AC11: 80.7 | AD11: MANTENIMIENTO | AE11: =AC11-AB11 -> 0.5 | AF11: =AA11-D11 -> -1.3
A12: COLMAN TOBIAS | F12: 62.4 | P12: RESER | U12: 61.6 | V12: 61 | W12: 61.5 | X12: 61.7 | Y12: 60.9 | Z12: 61.1 | AA12: 61.1 | AB12: 60.4 | AC12: 60 | AD12: RESERVA | AE12: =AC12-AB12 -> -0.4 | AF12: =AA12-F12 -> -1.3
A13: CORREA JOAQUIN | B13: 79.1 | C13: 80.7 | D13: 79 | E13: 78.6 | F13: 78.7 | G13: 79 | H13: 78.1 | J13: 78.9 | K13: 78.8 | L13: 77.9 | M13: 78.7 | O13: 80.1 | P13: 79.8 | Q13: 79.8 | R13: 79.9 | S13: 80.4 | U13: 82.7 | W13: 79.9 | X13: 80.7 | Z13: 80 | AA13: 79.4 | AB13: 80.2 | AC13: 79.9 | AD13: MANTENIMIENTO | AE13: =AC13-AB13 -> -0.3 | AF13: =AA13-B13 -> 0.3 | AP13: BAJAMOS 1 EN DESAYUNO
A14: DAURICIO MARTIN | B14: 80.7 | E14: 81 | H14: 82.2 | K14: 81.4 | L14: 80.9 | M14: 80.9 | N14: 80.6 | O14: 80.8 | P14: 82.1 | Q14: 80.8 | R14: 80.7 | S14: 79.6 | U14: 80 | V14: 80.7 | X14: 80.1 | Z14: 79.9 | AA14: 81.1 | AB14: 80.7 | AC14: 80.7 | AD14: MANTENIMIENTO | AE14: =AC14-AB14 -> 0 | AF14: =AA14-B14 -> 0.4 | AG14: ARQ | AP14: MAS 54 2804196734 (CHUBUT)
A15: DIMARCO ROCCO | D15: 73.1 | E15: 73.3 | F15: 73.2 | G15: 73.3 | H15: 72.9 | I15: 72.6 | J15: 72.6 | K15: 73.5 | L15: 73.1 | M15: 74.4 | N15: 73.3 | O15: 73.8 | P15: 74.1 | Q15: 73.9 | R15: 74.6 | S15: 74.4 | U15: 75.3 | V15: 74.1 | W15: 74.9 | X15: 73.9 | Y15: 73.4 | Z15: 73.7 | AA15: 75 | AB15: 74.1 | AC15: 74.1 | AD15: MANTENIMIENTO | AE15: =AC15-AB15 -> 0 | AF15: =AA15-D15 -> 1.9
A16: DOMIGUEZ DA SILVA DERLI | B16: 63.3 | C16: 63.9 | D16: 63.5 | E16: 64.5 | F16: 69 | G16: 63.5 | H16: 63.3 | I16: 63.3 | J16: 63.1 | K16: 63.8 | L16: 62.9 | M16: 62.8 | N16: 62.8 | O16: 63.3 | P16: 62.5 | Q16: 63.7 | R16: 63.1 | S16: 63.3 | U16: 63.8 | V16: 64 | W16: 63.6 | X16: 64 | Y16: 65 | Z16: 64.6 | AA16: 65 | AB16: 64.7 | AC16: 65.4 | AD16: MANTENIMIENTO | AE16: =AC16-AB16 -> 0.7 | AF16: =AA16-B16 -> 1.7
A17: FERREYRA TOBIAS | B17: 65.9 | C17: 64.3 | G17: 65.7 | K17: 65.7 | L17: 65.3 | N17: 67 | O17: 67.5 | P17: 66.9 | Q17: 65.9 | R17: 66 | U17: 65.9 | W17: 66.4 | X17: 65.3 | Z17: 65.8 | AA17: 65.8 | AB17: 64.9 | AC17: 64.6 | AD17: MANTENIMIENTO | AE17: =AC17-AB17 -> -0.3 | AF17: =AA17-B17 -> -0.1
A18: FIGUEROA JUAN | B18: 80.1 | C18: 80.8 | D18: 80.1 | E18: 78.7 | F18: 79.8 | G18: 80.6 | H18: 79.4 | K18: 79.9 | L18: 79.9 | N18: 80.8 | O18: 80.5 | P18: 81.3 | Q18: 80.6 | R18: 79.8 | S18: 80 | U18: 81.4 | V18: 81.5 | W18: 80.9 | X18: 80.2 | Y18: 81.7 | Z18: 80.5 | AA18: 79.8 | AB18: 79.9 | AC18: 79.1 | AD18: MANTENIMIENTO | AE18: =AC18-AB18 -> -0.8 | AF18: =AA18-B18 -> -0.3 | AG18: ARQ
A19: GARECA AGUSTIN | B19: 64.9 | C19: 65.7 | D19: 65.4 | E19: 66 | F19: 66.9 | G19: 67.6 | I19: 65.9 | J19: 68.5 | K19: 67.6 | L19: 68.2 | M19: 68.3 | P19: 70.3 | Q19: 69.7 | R19: 69.7 | S19: 70.4 | U19: 69.7 | X19: 69.4 | Y19: 71.3 | Z19: 70.8 | AA19: 71.5 | AB19: 70.5 | AC19: 71.3 | AD19: DESCENSO | AE19: =AC19-AB19 -> 0.8 | AF19: =AA19-B19 -> 6.6
A20: GAUNA AXEL | B20: 65.5 | C20: 65.2 | D20: 65.7 | E20: 66.5 | G20: 66.2 | H20: 66.3 | I20: 64.7 | J20: 65.2 | K20: 66.4 | L20: 66.1 | M20: 65.9 | N20: 66.2 | O20: 65.8 | P20: 66.4 | Q20: 67 | R20: 67 | S20: 67.5 | U20: 67.4 | V20: 68 | W20: 67.2 | X20: 67.7 | Y20: 67.8 | Z20: 67.4 | AA20: 68.1 | AB20: 67.8 | AC20: 68.3 | AD20: AUMENTO | AE20: =AC20-AB20 -> 0.5 | AF20: =AA20-B20 -> 2.6
A21: GRADIN VALENTIN | B21: 64.7 | D21: 64.4 | F21: . | G21: 65.1 | J21: 64.6 | M21: 63.8 | P21: RESER | R21: 63.6 | S21: 63.5 | V21: 62.7 | W21: 64.3 | Z21: 63.3 | AC21: 63 | AD21: MANTENIMIENTO/RESERVA | AE21: =AC21-AB21 -> 63 | AF21: =AA21-B21 -> -64.7
A22: JAUREGUI FACUNDO | B22: 88.6 | E22: 91 | K22: 89.6 | P22: 88.4 | R22: 89.3 | S22: 88.8 | U22: 87.9 | V22: 87.2 | W22: 88.2 | X22: 88.9 | Y22: 89.1 | Z22: 89.8 | AA22: 90.3 | AB22: 90.4 | AC22: 91.2 | AD22: RESERVA? DESCENSO | AE22: =AC22-AB22 -> 0.8 | AF22: =AA22-B22 -> 1.7
A23: MALDONADO NAHUEL | B23: 70 | C23: 69.7 | D23: 71.5 | E23: 70.2 | F23: 69.9 | H23: 70 | J23: 69.7 | K23: 70 | L23: 70.2 | M23: 70.1 | R23: 70.2 | S23: 69.7 | U23: 68.4 | Z23: 68.8 | AA23: 69.9 | AB23: 69.6 | AC23: 69.6 | AD23: AUMENTO | AE23: =AC23-AB23 -> 0 | AF23: =AA23-B23 -> -0.1
A24: MARTINEZ BRAIAN | B24: 77.2 | C24: 78.4 | D24: 76.9 | F24: 76.89 | J24: 78.3 | P24: RESER | R24: 80.1 | S24: 79.9 | U24: 80.4 | W24: 79.4 | X24: 80.5 | Y24: 80.4 | Z24: 80.3 | AA24: 80.4 | AB24: 80.5 | AC24: 81.5 | AD24: RESERVA | AE24: =AC24-AB24 -> 1 | AF24: =AA24-B24 -> 3.2
A25: MARTINEZ FABRIZIO | B25: 69.6 | F25: 71 | I25: 77.5 | P25: RESER | S25: 72.9 | W25: 73.6 | AD25: MANTENIMIENTO/RESERVA | AE25: =AC25-AB25 -> 0 | AF25: =AA25-B25 -> -69.6
A26: MENDEZ EZEQUIEL | B26: 74.8 | C26: 76.8 | G26: 77.7 | H26: 76.2 | J26: 75.9 | K26: 75.9 | L26: 77 | M26: 75.7 | N26: 75.6 | O26: 74.7 | P26: 75.5 | Q26: 75.4 | R26: 75.5 | S26: 76.4 | U26: 76.8 | V26: 75.6 | W26: 75.7 | X26: 76 | Y26: 76.8 | Z26: 75.1 | AA26: 76 | AB26: 75.9 | AC26: 75.9 | AD26: DESCENSO | AE26: =AC26-AB26 -> 0 | AF26: =AA26-B26 -> 1.2 | AH26: evaluar pliegues
A27: PERALTA TAHIEL (08) | C27: 67.5 | D27: 67.5 | P27: RESER | W27: R | AD27: RESERVA | AE27: =AC27-AB27 -> 0 | AF27: =AA27-C27 -> -67.5
A28: PERNIA GIROT | E28: 68.1 | F28: 67.8 | G28: 68.1 | H28: 68.1 | I28: 68.3 | J28: 67.9 | K28: 69.1 | L28: 69.3 | M28: 68.7 | N28: 68.5 | O28: 69.4 | P28: 69.5 | Q28: 69.1 | R28: 68.6 | S28: 68.9 | U28: 69.9 | V28: 69.9 | W28: 71 | Y28: 70 | Z28: 70.4 | AA28: 70.7 | AB28: 70.6 | AC28: 71.4 | AD28: MANTENIMIENTO | AE28: =AC28-AB28 -> 0.8 | AF28: =AA28-E28 -> 2.6
A29: PRAL RAMIRO | B29: 83.9 | C29: 81.8 | D29: 80.7 | F29: 82.2 | G29: 82.3 | H29: 84.1 | I29: 83.9 | J29: 83.4 | K29: 83.3 | L29: 85.6 | M29: 84 | N29: 85.5 | O29: 84.4 | P29: 83.4 | Q29: 85 | R29: 86.5 | S29: 85.3 | U29: 86.2 | V29: 85.8 | W29: 85.2 | X29: 85.7 | Y29: 85.2 | Z29: 86 | AA29: 86.4 | AB29: 87 | AC29: 86.2 | AD29: DESCENSO | AE29: =AC29-AB29 -> -0.8 | AF29: =AA29-B29 -> 2.5
A30: RODRIGUEZ LAUTARO | B30: 65.7 | C30: 67.8 | D30: 67.2 | E30: 64.6 | F30: 64.4 | G30: 65.3 | I30: 65.1 | J30: 64.8 | K30: 65.9 | L30: 64.8 | M30: 64.7 | N30: 65.7 | O30: 65.4 | P30: 65.3 | Q30: 64.4 | R30: 64.5 | S30: 65 | X30: 66.6 | Z30: 66.9 | AD30: DESCENSO | AE30: =AC30-AB30 -> 0 | AF30: =AA30-B30 -> -65.7
A31: SOSA THIAGO | B31: 80.1 | C31: 78.3 | D31: 78.9 | G31: 81.9 | H31: 81.3 | I31: 82 | J31: 82.2 | K31: 83.1 | L31: 84.4 | M31: 82.6 | N31: 83.4 | O31: 85.3 | P31: 85.2 | Q31: 85.2 | T31: 83.5 | U31: 85.2 | V31: 83.9 | X31: 84.7 | Y31: 83.7 | Z31: 85 | AA31: 84.1 | AB31: 86.3 | AC31: 85.3 | AD31: AUMENTO | AE31: =AC31-AB31 -> -1 | AF31: =AA31-B31 -> 4
A32: URIBE TOMAS | B32: 63.2 | D32: 65.4 | F32: 64.6 | G32: 64.9 | J32: 66.1 | K32: 67.4 | L32: 66.7 | M32: 65.1 | N32: 66.2 | O32: 67.8 | P32: 67.8 | Q32: 68.4 | R32: 68.6 | S32: 68.7 | W32: 4ta | AD32: RESERVA | AE32: =AC32-AB32 -> 0 | AF32: =AA32-B32 -> -63.2
A33: VIGLIOCO BRUNO | B33: 74.5 | C33: 76.5 | D33: 76.2 | E33: 74.5 | F33: 74.6 | G33: 75.1 | H33: 75.7 | I33: 75.7 | J33: 76.4 | K33: 75.4 | L33: 76.5 | M33: 75.4 | N33: 76 | O33: 75.2 | P33: 76 | Q33: 76.6 | R33: 77 | S33: 77.6 | V33: 76 | W33: 76.8 | X33: 78.8 | Y33: 77.3 | Z33: 77.4 | AA33: 77.3 | AB33: 77.8 | AC33: 77.4 | AD33: DESCENSO | AE33: =AC33-AB33 -> -0.4 | AF33: =AA33-B33 -> 2.8
A34: YAMAGUCHI | F34: 64.9 | P34: RESER | W34: R | AD34: RESERVA | AE34: =AC34-AB34 -> 0 | AF34: =AA34-B34 -> 0
A35: SOTO MARTIN | S35: 82.6 | W35: R | AD35: RESERVA | AE35: =AC35-AB35 -> 0 | AF35: =AA35-S35 -> -82.6
A36: MANSUR RODRIGO | U36: 78.2 | V36: 78.2 | W36: 77.5 | X36: 78.7 | Y36: 79.1 | Z36: 78.8 | AA36: 78.5 | AB36: 79.6 | AC36: 79.8 | AD36: DESCENSO | AE36: =AC36-AB36 -> 0.2 | AF36: =AA36-U36 -> 0.3
A37: PENSIÓN
A40: CASTRO NAHUEL | B40: 64.7 | C40: 64.4 | AE40: =K40-D40 -> 0
A41: CONESA FRANCO | B41: 66.4 | C41: 65.4 | AE41: =K41-D41 -> 0
A42: BASTISTELA TISIANO | B42: 71.3 | C42: 71.5 | D42: 71.6 | E42: 70.8 | G42: 73.4 | H42: 74.2 | J42: 75.3 | K42: 75.1 | L42: 75.3 | M42: 76.2 | N42: 77.2 | O42: 77.6 | P42: 77.7 | Q42: 78.2 | R42: 78.7 | S42: 78.6 | U42: no viene mas | AD42: MANTENIMIENTO

Sheet 6TA (08)
A1: CAH - 6ta div -25
A2: JUGADOR | B2: 2024 | C2: 45679 | D2: 45686 | E2: 45693 | F2: 45728 | G2: 45735 | H2: 45749 | I2: 45756 | J2: 45763 | K2: 45770 | L2: 45777 | M2: 45784 | N2: 45791 | O2: 45798 | P2: 45805 | Q2: 45812 | R2: 45819 | S2: 45826 | T2: 45849 | U2: 45861 | V2: 45868 | W2: 45875 | X2: 45882 | Y2: 45889 | Z2: 45896 | AA2: 45903 | AB2: 45910 | AC2: 45917 | AD2: PAUTAS | AE2: DIFERENCIA sem | AF2: DIFERENCIA ANUAL
A3: AARON SILVA | B3: 78.9 | E3: 78.9 | F3: 78.9 | G3: 79.7 | I3: 79.2 | R3: 76.8 | AA3: 77.6 | AB3: 78.3 | AE3: =AC3-AB3 -> -78.3 | AF3: =AA3-B3 -> -1.3
A4: ACOSTA MATEO | B4: 77.5 | C4: 77.4 | E4: 75.6 | F4: 76.6 | G4: 76 | H4: 76.6 | I4: 76.6 | K4: 77.1 | L4: 77.5 | N4: 78.2 | Q4: 78.2 | R4: 77.9 | S4: 78.5 | T4: 78.5 | U4: 78.6 | V4: 78.8 | W4: 77.3 | Y4: 79.4 | Z4: 77.7 | AA4: 78.4 | AB4: 78.4 | AC4: 78.6 | AD4: DESCENSO | AE4: =AC4-AB4 -> 0.2 | AF4: =AA4-B4 -> 0.9
A5: ALMENDARIZ MARTIN | C5: 62.3 | D5: 62.5 | E5: 63.3 | F5: 68.3 | G5: 63.3 | H5: 63.1 | I5: 63.4 | K5: 62.6 | L5: 63 | M5: 64.3 | N5: 64 | O5: 64.1 | P5: 64.4 | Q5: 65.1 | R5: 65.7 | S5: 65.4 | T5: 66.4 | U5: 65.9 | V5: 65.5 | W5: 65.5 | Y5: 65.6 | Z5: 66.9 | AA5: 65.9 | AB5: 66.3 | AC5: 65.3 | AD5: AUMENTO | AE5: =AC5-AB5 -> -1 | AF5: =AA5-C5 -> 3.6
A6: AQUINO LAUTARO | C6: 77.6 | D6: 76.9 | E6: 76.4 | F6: 76.6 | G6: 76.6 | H6: 76.2 | I6: 76.4 | K6: 76.1 | L6: 76.6 | M6: 76 | N6: 76.3 | O6: 77.6 | P6: 76.8 | Q6: 78 | R6: 77.5 | S6: 77.3 | T6: 77.4 | U6: 78.4 | V6: 77.4 | W6: 77.3 | Y6: 77.2 | Z6: 77.9 | AA6: 77 | AB6: 78.6 | AC6: 77.9 | AD6: MANTENIMIENTO | AE6: =AC6-AB6 -> -0.7 | AF6: =AA6-C6 -> -0.6
A7: BALTAR AXEL | B7: 71 | C7: 69.9 | D7: 70.5 | E7: 72.6 | F7: 72.1 | G7: 72 | H7: 72 | I7: 72.1 | K7: 71 | L7: 70.9 | M7: 71.8 | N7: 71.9 | Q7: 71.9 | R7: 72 | S7: 71.6 | T7: 72.4 | U7: 71 | V7: 73.2 | W7: 72.3 | Y7: 72.2 | Z7: 72.7 | AA7: 71.4 | AB7: 71.8 | AC7: 71.4 | AE7: =AC7-AB7 -> -0.4 | AF7: =AA7-B7 -> 0.4
A8: BENITEZ DANTE | B8: 75.1 | C8: 74.8 | D8: 75 | E8: 75.6 | F8: 75.7 | G8: 75.2 | H8: 76.2 | I8: 76.4 | K8: 76 | L8: 77.1 | M8: 77.1 | N8: 75.2 | O8: 75.4 | P8: 76.9 | Q8: 77.6 | R8: 77.6 | S8: 77.6 | T8: 78 | V8: 78.1 | W8: 76.9 | Y8: 77.9 | Z8: 78 | AA8: 77.5 | AB8: 77.8 | AC8: 76.9 | AD8: MANTENIMIENTO | AE8: =AC8-AB8 -> -0.9 | AF8: =AA8-B8 -> 2.4
A9: BENITEZ IAN | B9: 76.3 | C9: 75.6 | D9: 73.5 | O9: 74.9 | P9: 76.4 | Q9: 77.5 | R9: 77.5 | S9: 77.4 | T9: 77.4 | U9: 77.4 | V9: 78.4 | W9: 78.7 | Z9: L | AA9: 79.4 | AB9: 78.9 | AC9: 78.8 | AD9: MANTENIMIENTO | AE9: =AC9-AB9 -> -0.1 | AF9: =AA9-B9 -> 3.1
A10: BORJA AXEL | B10: 73.8 | D10: 73.2 | G10: 70.6 | H10: 71 | K10: 71.1 | L10: 71.8 | P10: 72.9 | Q10: 72.7 | R10: 72.6 | S10: 73.6 | T10: 73.5 | V10: 73 | Y10: 74.7 | Z10: 73.8 | AA10: 74.4 | AB10: 74.3 | AC10: 74.7 | AE10: =AC10-AB10 -> 0.4 | AF10: =AA10-B10 -> 0.6
A11: CACERES DYLAN | B11: 75.6 | C11: 74.8 | D11: 74.3 | H11: 72.1 | N11: 75 | R11: 74.4 | S11: 75.2 | T11: 76.8 | U11: 77.5 | V11: 77 | W11: 77.6 | Y11: 77.3 | Z11: 78 | AA11: 78.8 | AB11: 77 | AC11: 77.6 | AD11: DESCENSO | AE11: =AC11-AB11 -> 0.6 | AF11: =AA11-B11 -> 3.2
A12: CAGIANO IGNACIO | C12: 72.3 | D12: 72.3 | F12: 72.4 | G12: 71.7 | H12: 70.9 | I12: 70.9 | K12: 70.4 | L12: 70.4 | M12: 68.4 | N12: 70.8 | O12: 71.2 | P12: 70.6 | Q12: 69.9 | R12: 70.3 | S12: 70 | T12: 70.1 | U12: 68.5 | V12: 69.4 | W12: 69 | Y12: 69.7 | Z12: 68.9 | AA12: 68.9 | AB12: 69.6 | AC12: 70 | AD12: DESCENSO | AE12: =AC12-AB12 -> 0.4 | AF12: =AA12-C12 -> -3.4
A13: CARABALLO BENJAMIN | B13: 59.9 | C13: 61.3 | D13: 60.3 | E13: 60.7 | F13: 60.3 | G13: 60.1 | H13: 60 | I13: 59.6 | K13: 60 | L13: 60.8 | M13: 61.4 | N13: 60 | O13: 60.7 | P13: 60.9 | Q13: 61.2 | R13: 62.1 | S13: 61.8 | T13: 63 | U13: 62.7 | V13: 62.4 | W13: 62.1 | Y13: 62 | Z13: 61.9 | AA13: 61.6 | AB13: 62.4 | AC13: 62.9 | AD13: MANTENIMIENTO | AE13: =AC13-AB13 -> 0.5 | AF13: =AA13-B13 -> 1.7
A14: CATANZANO LAUTARO | B14: 84 | C14: 87.3 | D14: 85.4 | F14: 84 | G14: 84 | K14: 83.1 | T14: 83.1 | V14: 83.6 | X14: 84.1 | AB14: 84.7 | AE14: =AC14-AB14 -> -84.7 | AF14: =AA14-B14 -> -84
A15: DE ASIS JONATHAN | B15: 60.6 | C15: 61.6 | E15: 59.6 | H15: 60 | M15: 59.9 | N15: 58.4 | Q15: 59 | R15: 60.2 | S15: 59.8 | T15: 61 | U15: 62.1 | W15: 61.8 | Y15: 61.5 | Z15: 60.6 | AA15: 61.9 | AB15: 62.9 | AC15: 62.6 | AD15: MANTENIMIENTO | AE15: =AC15-AB15 -> -0.3 | AF15: =AA15-B15 -> 1.3
A16: DIAZ ALAN | B16: 73.2 | D16: 71.3 | F16: 72.2 | G16: 72.5 | H16: 73.2 | K16: 73.2 | L16: 73.6 | Q16: 72.5 | R16: 72.6 | S16: 71.7 | T16: 72.3 | U16: 72.7 | V16: 74.2 | W16: 73.7 | Z16: 73.9 | AA16: 74.3 | AC16: 75.4 | AD16: MANTENIMIENTO | AE16: =AC16-AB16 -> 75.4 | AF16: =AA16-B16 -> 1.1
A17: FERNANDEZ AMIR | F17: 75.8 | H17: 75.9 | I17: 76.3 | K17: 75.3 | L17: 75.3 | M17: 75.4 | N17: 75.9 | O17: 76.3 | P17: 76.2 | Q17: 75.5 | R17: 77.2 | S17: 75.5 | T17: 75.6 | U17: 76.9 | V17: 76.9 | W17: 76.8 | Y17: 76.3 | Z17: 75.1 | AA17: 75.7 | AB17: 75.4 | AC17: 75.8 | AD17: MANTENIMIENTO | AE17: =AC17-AB17 -> 0.4 | AF17: =AA17-F17 -> -0.1
A18: GARIGLIO ENZO | C18: 78.2 | D18: 77.4 | E18: 77 | F18: 76.7 | G18: 76.3 | H18: 71.4 | I18: 77.1 | K18: 77.8 | L18: 78.2 | M18: 78.5 | N18: 78.7 | O18: 79.9 | P18: 80 | Q18: 81 | R18: 79.6 | T18: 79.2 | U18: 78.5 | V18: 79.5 | W18: 79.6 | Y18: 80 | Z18: 78.9 | AA18: 78.5 | AB18: 78.6 | AC18: 79.6 | AD18: DESCENSO | AE18: =AC18-AB18 -> 1 | AF18: =AA18-C18 -> 0.3
A19: GARCES DYLAN | B19: 64.5 | I19: 72.8 | U19: 67.8 | V19: 68.1 | W19: 67.4 | X19: - | Y19: 67.2 | Z19: 66.9 | AA19: 67 | AB19: 67.2 | AC19: 65.7 | AE19: =AC19-AB19 -> -1.5 | AF19: =AA19-B19 -> 2.5
A20: GUERRERO AGUSTIN | B20: 62.8 | C20: 63.3 | F20: 62.1 | G20: 61.1 | H20: 61.3 | I20: 61.8 | K20: 63 | L20: 63.7 | M20: 62.5 | N20: 62.4 | O20: 63.2 | P20: 63 | Q20: 64.5 | R20: 63.7 | S20: 63.5 | T20: 63.9 | U20: 63.8 | V20: 64.5 | W20: 64.2 | Z20: 65.3 | AA20: 65.7 | AB20: 65.3 | AC20: 65.2 | AD20: MANTENIMIENTO | AE20: =AC20-AB20 -> -0.1 | AF20: =AA20-B20 -> 2.9
A21: GUERRERO ENZO | B21: 61.5 | C21: 60.1 | D21: 60.4 | E21: 60.7 | F21: 60.5 | I21: 62 | J21: 62.7 | K21: 61.8 | O21: 59.1 | R21: 59.6 | S21: 60.8 | T21: 61.9 | W21: 61.7 | AB21: 61.3 | AC21: 61.1 | AD21: RESERVA | AE21: =AC21-AB21 -> -0.2 | AF21: =AA21-B21 -> -61.5
A22: INSAURRALDE URIEL | B22: 70.8 | C22: 73.8 | D22: 73.3 | F22: 73 | G22: 73.2 | H22: 71.6 | K22: 72.5 | L22: 71.9 | M22: 72.4 | N22: 71.9 | O22: 71.7 | S22: 70.1 | V22: 70.8 | W22: 70.7 | Z22: 70.6 | AA22: 70.8 | AB22: 70.5 | AE22: =AC22-AB22 -> -70.5 | AF22: =AA22-B22 -> 0
A23: LEGUIZAMON ARON | B23: 56.7 | C23: 58.7 | D23: 58.2 | K23: 61.8 | M23: 61.8 | P23: 62.5 | Q23: 62.4 | R23: 62.8 | S23: 63.6 | T23: 62.9 | U23: 62.2 | V23: 63.6 | W23: 63.4 | Y23: 64.4 | Z23: 63.6 | AA23: 63.1 | AB23: 64.8 | AD23: DESCENSO | AE23: =AC23-AB23 -> -64.8 | AF23: =AA23-B23 -> 6.4
A24: LOPEZ RAMIRO | B24: 64.8 | C24: 64.7 | D24: 64.4 | E24: 62.5 | F24: 63.5 | G24: 63 | H24: 62.8 | I24: 63 | K24: 63.1 | L24: 63.2 | M24: 62.9 | N24: 63.2 | O24: 63.6 | P24: 63.9 | Q24: 63.8 | R24: 63.4 | S24: 64.4 | T24: 63.9 | U24: 64.1 | V24: 63.7 | W24: 63.7 | Y24: 63.1 | Z24: 63 | AA24: 62.6 | AB24: 63 | AC24: 63 | AD24: MANTENIMIENTO | AE24: =AC24-AB24 -> 0 | AF24: =AA24-B24 -> -2.2
A25: MACIEL LUCAS | B25: 65.8 | D25: 67 | E25: 67 | F25: 65.6 | G25: 66.8 | H25: 66 | I25: 66.1 | K25: 66.5 | L25: 67.2 | M25: 67 | N25: 67.4 | O25: 66.8 | P25: 66.9 | R25: 68 | S25: 69.2 | T25: 68.8 | W25: 67.5 | AD25: RESERVA | AE25: =AC25-AB25 -> 0 | AF25: =AA25-B25 -> -65.8
A26: MATELLAN SAMUEL | B26: 65.4 | C26: 69.7 | D26: 69.5 | F26: 69.3 | G26: 69 | H26: 69.6 | I26: 70.1 | K26: 69.5 | L26: 69.3 | M26: 70.6 | N26: 70.4 | O26: 70.6 | P26: 71.3 | R26: 69.9 | S26: 69.4 | U26: 71.3 | V26: 71.6 | W26: 70.7 | Y26: 72.1 | Z26: 72.3 | AA26: 72.5 | AB26: 71.9 | AC26: 73.9 | AE26: =AC26-AB26 -> 2 | AF26: =AA26-B26 -> 7.1
A27: NUÑEZ LAURENCIO | B27: 61.5 | C27: 63.3 | D27: 66.4 | G27: 66.4 | H27: 65.7 | N27: 65.9 | Q27: 66.8 | S27: 66.8 | T27: 66.9 | U27: 66.7 | V27: 66.8 | W27: 67.4 | Y27: 67.4 | Z27: 68 | AA27: 67.7 | AB27: 68.6 | AC27: 68.2 | AD27: MANTENIMIENTO | AE27: =AC27-AB27 -> -0.4 | AF27: =AA27-B27 -> 6.2
A28: NUÑEZ LAUTARO | E28: 64 | G28: 63.3 | H28: 61.8 | I28: 63 | K28: 63.7 | L28: 61.5 | N28: 63.5 | T28: 64.6 | U28: 65 | V28: 65.1 | W28: 65.4 | Z28: 65.1 | AA28: 64.7 | AB28: 65.2 | AC28: 65.7 | AE28: =AC28-AB28 -> 0.5 | AF28: =AA28-E28 -> 0.7
A29: PARGA THIAGO | D29: 83.4 | E29: 83.1 | F29: 82.8 | G29: 82.5 | H29: 83.4 | I29: 83.9 | K29: 83.7 | L29: 84.9 | M29: 84.5 | P29: 81.4 | R29: 84.7 | AD29: RESERVA | AE29: =AC29-AB29 -> 0 | AF29: =AA29-D29 -> -83.4
A30: PECILE MATIAS | B30: 67 | C30: 68.9 | D30: 68.9 | E30: 70.7 | F30: 70.3 | G30: 69.5 | H30: 69.6 | I30: 69.8 | K30: 70.8 | L30: 71 | M30: 69.6 | O30: 70.8 | R30: 71 | S30: 71.9 | T30: 71.8 | U30: 72.3 | V30: 71.3 | W30: 72.5 | Y30: 72 | Z30: 72.1 | AA30: 71.1 | AB30: 71 | AC30: 71.3 | AD30: MANTENIMIENTO/RESERVA | AE30: =AC30-AB30 -> 0.3 | AF30: =AA30-B30 -> 4.1
A31: POZA AYRTON | B31: 64.3 | C31: 64.6 | D31: 63.4 | F31: 64.1 | G31: 62.9 | H31: 65.2 | I31: 64.5 | K31: 63.4 | L31: 64.3 | M31: 64.2 | O31: 65 | P31: 65.8 | Q31: 65.2 | R31: 65.5 | S31: 67.4 | T31: 67.3 | U31: 66.7 | V31: 66.9 | W31: 66.9 | Y31: 67 | Z31: 67.3 | AA31: 67.5 | AB31: 67 | AC31: 66.8 | AE31: =AC31-AB31 -> -0.2 | AF31: =AA31-B31 -> 3.2
A32: RAYNELI SANTINO | B32: 67.3 | C32: 66.5 | D32: 66.8 | E32: 68.1 | F32: 68.4 | G32: 67.3 | H32: 68.1 | I32: 67.9 | K32: 67.5 | R32: RESERVA | S32: 69 | T32: 69.7 | AC32: 69.8 | AD32: RESERVA | AE32: =AC32-AB32 -> 69.8 | AF32: =AA32-B32 -> -67.3
A33: SAPAYA ELIAS | B33: 67.2 | C33: 66.5 | D33: 67 | F33: 67.6 | G33: 67.9 | H33: 68.7 | I33: 66.8 | K33: 67.6 | L33: 67.7 | M33: 68.7 | N33: 67.4 | O33: 67.6 | P33: 67.1 | Q33: 68 | R33: 68 | S33: 68 | T33: 69.5 | U33: 69.1 | V33: 68.3 | W33: 69.2 | Y33: 70.2 | Z33: 68.4 | AA33: 67.9 | AB33: 69.2 | AC33: 67.5 | AD33: MANTENIMIENTO | AE33: =AC33-AB33 -> -1.7 | AF33: =AA33-B33 -> 0.7
A34: VENTRE FRANCISCO | B34: 83.6 | C34: 84.9 | D34: 84.8 | E34: 82.3 | F34: 83 | H34: 83.7 | I34: 84.8 | K34: 84.9 | L34: 85.6 | M34: 83.8 | N34: 83.2 | O34: 84.1 | P34: 84.2 | Q34: 84.2 | R34: 85 | S34: 84.7 | T34: 84.4 | U34: 86.4 | V34: 85.5 | W34: 85.4 | Y34: 84.6 | Z34: 85.7 | AA34: 84.9 | AB34: 85.9 | AC34: 84.5 | AD34: DESCENSO | AE34: =AC34-AB34 -> -1.4 | AF34: =AA34-B34 -> 1.3 | AG34: 2352553146
A35: TROTA MATIAS | AA35: 51.4 | AB35: 51.4 | AC35: 51.9 | AE35: =AC35-AB35 -> 0.5
A36: OLARTE JUAN PABLO | T36: 94.1 | U36: 94 | V36: 94.3 | W36: 94 | Y36: 94.3 | Z36: 95.1 | AA36: 95.3 | AB36: 96 | AC36: 94.7 | AE36: =AC36-AB36 -> -1.3
A37: PENSIÓN
A38: SILVA | AC38: 78.9
A43: ALZOGARAY MATEO | C43: 73.3 | D43: 73.3 | E43: 73.6 | R43: no mas | AE43: =K43-D43 -> -73.3
A44: FERNANDEZ JOAQUIN | C44: 80.2 | D44: 78.7 | F44: 76.2 | R44: no mas | AE44: =K44-D44 -> -78.7
...

Sheet 7MA (09)
A1: CAH - 7ma div -25
A2: JUGADOR | B2: 2024 | C2: 45679 | D2: 45686 | E2: 45693 | F2: 45728 | G2: 45735 | H2: 45749 | I2: 45756 | J2: 45763 | K2: 45770 | L2: 45777 | M2: 45784 | N2: 45791 | O2: 45798 | P2: 45805 | Q2: 45812 | R2: 45819 | S2: 45826 | T2: 45849 | U2: 45861 | V2: 45868 | W2: 45875 | X2: 45882 | Y2: 45889 | Z2: 45903 | AA2: 45910 | AB2: 45917 | AC2: PAUTAS | AD2: DIFERENCIA sem | AE2: DIFERENCIA ANUAL
A3: ACOSTA BRANDON | C3: 57.9 | D3: 59.6 | F3: 58.7 | H3: 58.1 | I3: 58.1 | J3: 58 | K3: 59.2 | M3: 59 | N3: 58 | O3: 58 | P3: 58.2 | Q3: 58.7 | R3: 59 | S3: 59.5 | T3: 58.4 | U3: 59.3 | V3: 58.9 | X3: 58 | Z3: 59 | AA3: 60 | AC3: MANTENIMIENTO | AD3: =AB3-AA3 -> -60
A4: AGGIO TOMAS | B4: 67.6 | C4: 67.6 | D4: 66.8 | E4: 66 | F4: 67 | G4: 67.2 | H4: 67.7 | I4: 68.9 | J4: 68 | K4: 68.2 | L4: 67.8 | M4: 68.6 | N4: 69.9 | O4: 69.6 | P4: 69.9 | Q4: 69.4 | R4: 70.4 | S4: 69.8 | T4: 70.1 | U4: 70.5 | V4: 70.3 | W4: 70.7 | X4: 70.4 | Y4: 69.9 | Z4: 71.6 | AA4: 70.8 | AB4: 70.1 | AC4: DESCENSO | AD4: =AB4-AA4 -> -0.7 | AF4: 27-8 70,4
A5: ALVAREZ THIAGO | B5: 68.5 | C5: 67.9 | D5: 68 | E5: 68.2 | G5: 65.6 | H5: 66.8 | I5: 67.4 | J5: 68.9 | K5: 69.6 | L5: 67.9 | N5: 68.2 | O5: 69 | P5: 70.1 | Q5: 70.5 | R5: 70.6 | S5: 70.9 | T5: 71 | U5: 71.4 | V5: 71.1 | W5: 71.2 | X5: 70.7 | Y5: 71.1 | Z5: 70.9 | AA5: 70.9 | AB5: 70.5 | AC5: DESCENSO | AD5: =AB5-AA5 -> -0.4
A6: BACHES AGUSTIN | B6: 60.4 | C6: 58.6 | D6: 59.2 | E6: 60 | F6: 59.9 | G6: 59.6 | H6: 60 | I6: 61.1 | J6: 60.5 | K6: 67.1 | M6: 61.7 | N6: 61.5 | O6: 61.4 | Q6: 60.9 | R6: 60.8 | S6: 61.5 | T6: 61.7 | U6: 61.4 | V6: 62.1 | W6: 62.1 | X6: 63 | Y6: 62.7 | Z6: 61.6 | AA6: 62.3 | AB6: 62.1 | AC6: MANTENIMIENTO | AD6: =AB6-AA6 -> -0.2
A7: BALSANO AGUSTIN | B7: 64 | C7: 66 | D7: 64.2 | E7: 66 | F7: 65 | G7: 65.7 | H7: 66.4 | I7: 65.8 | J7: 66.9 | M7: 67 | N7: 66.5 | O7: 67.5 | P7: 67.5 | Q7: 67.7 | R7: 67.3 | S7: 68 | U7: 66.9 | V7: 65.8 | W7: 66.1 | X7: 65.5 | Y7: 66.8 | Z7: 66.4 | AA7: 65.9 | AB7: 66 | AC7: MANTENIMIENTO | AD7: =AB7-AA7 -> 0.1
A8: CASTILLO IAN | B8: 58.4 | D8: 57.3 | E8: 58.2 | F8: 57.9 | G8: 57.1 | H8: 57.6 | I8: 57.8 | J8: 57 | O8: 57.4 | P8: 58.4 | Q8: 59.1 | R8: 58.7 | S8: 60.1 | T8: 60.2 | U8: 60.7 | V8: 60 | W8: 59.1 | X8: 60.7 | Z8: 60.7 | AA8: 60.5 | AB8: 61.3 | AC8: DESCENSO | AD8: =AB8-AA8 -> 0.8
A9: CEBALLOS NAZARENO | B9: 62.9 | C9: 65.5 | D9: 63.5 | E9: 63.1 | F9: 63.7 | G9: 64 | H9: 62.7 | I9: 63.7 | J9: 64.9 | K9: 63.2 | L9: 63.6 | M9: 67 | N9: 65.3 | O9: 66.2 | P9: 66.7 | Q9: 65.7 | R9: 65.6 | S9: 65.9 | T9: 66.1 | U9: 67.4 | V9: 67.4 | W9: 67.2 | X9: 68.3 | Y9: 68.7 | Z9: 69 | AA9: 69.2 | AB9: 69.6 | AC9: MANTENIMIENTO | AD9: =AB9-AA9 -> 0.4
A10: CHAPARRO MATEO | B10: 64.6 | C10: 64.8 | D10: 64.2 | E10: 63.4 | F10: 63.9 | G10: 64.7 | H10: 64.5 | J10: 64.7 | K10: 66 | L10: 65.2 | M10: 65.8 | O10: 66.4 | P10: 66.7 | Q10: 66.5 | R10: 65.8 | S10: 66.4 | T10: 66.6 | U10: 67.1 | V10: 66.6 | W10: 65.9 | X10: 65.4 | AC10: DESCENSO | AD10: =AB10-AA10 -> 0
A11: COLMAN SANTIAGO | B11: 65.5 | C11: 65.5 | D11: 65.2 | E11: 65.2 | F11: 65 | G11: 65.1 | H11: 64.4 | I11: 63.9 | J11: 64.2 | K11: 63.8 | L11: 64.5 | M11: 65.7 | O11: 64.9 | P11: 66 | R11: 65.1 | S11: 65 | T11: 65.2 | U11: 66.2 | V11: 67 | W11: 66.6 | X11: 66.7 | Z11: 68 | AA11: 68.1 | AB11: 68.3 | AC11: MANTENIMIENTO | AD11: =AB11-AA11 -> 0.2
A12: CONDE LUCIANO | B12: 66.6 | C12: 67.5 | D12: 68.2 | E12: 67.7 | F12: 67.7 | G12: 67.6 | H12: 68.4 | J12: 70.1 | K12: 71.6 | M12: 71.4 | N12: 71.9 | O12: 71.8 | Q12: 71.7 | R12: 73.6 | S12: 72.6 | T12: 72.5 | V12: 72.1 | X12: 72.5 | Z12: 72.4 | AA12: 72.4 | AB12: 73.2 | AC12: DESCENSO | AD12: =AB12-AA12 -> 0.8
A13: CORREA Juan marton | W13: 65.5 | X13: 65.2 | Z13: 67.1 | AA13: 66.1 | AB13: 66.2 | AD13: =AB13-AA13 -> 0.1
A14: DATA LUCAS | B14: 70.7 | C14: 70.4 | D14: 70.4 | E14: 71.5 | F14: 71.9 | G14: 71.9 | H14: 72.6 | I14: 72.7 | J14: 72.5 | K14: 72.9 | N14: 73.5 | Q14: 73.3 | R14: 71.9 | S14: 71.3 | T14: 72 | U14: 71.2 | V14: 70.7 | W14: 70.9 | X14: 70.8 | Y14: 70.5 | Z14: 69.1 | AA14: 70.1 | AB14: 68.9 | AC14: DESCENSO | AD14: =AB14-AA14 -> -1.2
A15: DE GREGORIO BRIAN | B15: 66.6 | C15: 66.8 | D15: 66.7 | E15: 65.5 | F15: 67 | G15: 66.6 | H15: 66.8 | I15: 67 | J15: 65.4 | K15: 66.9 | L15: 67.7 | M15: 67.8 | O15: 69 | P15: 66.7 | Q15: 68.7 | R15: 68.4 | S15: 69.6 | T15: 68.9 | U15: 68.5 | V15: 69.7 | W15: 67.4 | X15: 67.2 | Z15: 68.9 | AA15: 68.9 | AB15: 68.9 | AC15: MANTENIMIENTO | AD15: =AB15-AA15 -> 0
A16: DEL BLANCO MATEO | C16: 78.6 | E16: 76.7 | F16: 76.6 | G16: 76.2 | H16: 75.2 | I16: 74.6 | J16: 75.5 | K16: 76.7 | L16: 77 | M16: 76.7 | N16: 76 | O16: 76.9 | P16: 77 | Q16: 77,.5 | R16: 77.8 | S16: 78.7 | T16: 78.4 | U16: 77.8 | V16: 77.4 | W16: 77.4 | X16: 77.2 | Z16: 77.9 | AA16: 78.4 | AB16: 74.3 | AC16: MANTENIMIENTO | AD16: =AB16-AA16 -> -4.1
A17: DOMINGUEZ AYRTON | B17: 76.7 | C17: 76.4 | D17: 77.5 | E17: 77.1 | F17: 76.8 | G17: 76.8 | H17: 76.3 | J17: 76.1 | M17: 77.5 | N17: 78.1 | O17: 77.3 | P17: 77.3 | Q17: 76.1 | R17: 77 | S17: 77.7 | T17: 77.7 | U17: 76.7 | V17: 78.1 | W17: 77.8 | AC17: DESCENSO | AD17: =AB17-AA17 -> 0
A18: FALIA SANTIAGO | C18: 64 | D18: 64.5 | E18: 62.8 | F18: 62.2 | G18: 62.3 | H18: 62.2 | I18: 63.4 | J18: 63.2 | K18: 63.2 | L18: 62.8 | M18: 62.7 | N18: 62.1 | O18: 63 | P18: 62.6 | Q18: 61.7 | R18: 62.9 | S18: 63.2 | T18: 62.8 | U18: 63.9 | V18: 63.4 | W18: 63.4 | X18: 63.9 | Y18: 63.5 | Z18: 64 | AA18: 65.5 | AB18: 66 | AC18: DESCENSO | AD18: =AB18-AA18 -> 0.5
A19: FERNANDEZ AXEL | B19: 69.2 | C19: 69.1 | D19: 68.3 | F19: 66.2 | G19: 65.1 | H19: 66 | I19: 66 | J19: 67.1 | K19: 67.9 | L19: 67.8 | M19: 67.3 | N19: 67.8 | O19: 69.5 | P19: 68.8 | Q19: 69 | R19: 68.5 | S19: 68.7 | T19: 69 | U19: 69.6 | V19: 70.7 | W19: 71 | X19: 70.2 | Y19: 71.2 | Z19: 71.1 | AA19: 69.9 | AB19: 71.5 | AC19: MANTENIMIENTO | AD19: =AB19-AA19 -> 1.6
A20: FERNANDEZ SANTINO | B20: 65.7 | C20: 66 | D20: 66.4 | E20: 65.6 | F20: 65.1 | G20: 63.4 | H20: 77.4 | I20: 78.3 | J20: 64.3 | K20: 65.4 | L20: 64.8 | M20: 65 | O20: 64.9 | P20: 63.8 | Q20: 64.6 | R20: 64.2 | S20: 65.1 | T20: 66 | U20: 67.4 | V20: 68.1 | W20: 68.4 | Y20: 68.4 | Z20: 67.8 | AA20: 68.5 | AC20: DESCENSO | AD20: =AB20-AA20 -> -68.5
A21: FERNANDEZ JOAQUIN | C21: 77.9 | D21: 77.7 | E21: 76.5 | G21: 76.2 | H21: 62.9 | I21: 64.4 | J21: 77.7 | K21: 77.9 | L21: 77.2 | M21: 77.8 | N21: 77.7 | O21: 78.6 | P21: 79.3 | Q21: 77 | R21: 78.1 | S21: 76.6 | T21: 77 | U21: 78.8 | V21: 78.4 | W21: 78.8 | X21: 78.7 | Y21: 78.7 | Z21: 78.8 | AA21: 78.8 | AC21: AUMENTO | AD21: =AB21-AA21 -> -78.8
A22: FUENTES ALEJO | B22: 69.9 | C22: 68.4 | D22: 69.2 | E22: 70.4 | F22: 69.7 | G22: 69.6 | H22: 69.9 | J22: 72.1 | K22: 72.6 | L22: 72.1 | M22: 72.5 | N22: 71 | O22: 71.6 | Q22: 71.4 | R22: 71.4 | S22: 72.4 | T22: 73.5 | U22: 74.4 | V22: 75.3 | W22: 74.5 | X22: 75.2 | Z22: 75 | AA22: 74.8 | AB22: 74.8 | AC22: MANTENIMIENTO | AD22: =AB22-AA22 -> 0
A23: ILARION ELISEO | B23: 62.7 | C23: 63.9 | D23: 61.9 | E23: 64.5 | G23: 64.8 | H23: 64.5 | I23: 65.6 | J23: 64.8 | K23: 66.5 | L23: 65.7 | N23: 65.5 | O23: 64.7 | P23: 65 | Q23: 65.2 | R23: 65.4 | S23: 66.4 | T23: 66.2 | U23: 66 | V23: 65.5 | X23: 65.2 | Y23: 64.5 | Z23: 65.3 | AC23: AUMENTO | AD23: =AB23-AA23 -> 0
A24: LUNA DYLAN | B24: 58.8 | C24: 58.3 | D24: 58.1 | E24: 57.7 | F24: 58 | G24: 58.2 | H24: 58.5 | J24: 58.5 | K24: 58.9 | M24: 59.6 | N24: 59.3 | O24: 59.9 | P24: 59.1 | Q24: 59.7 | R24: 59.7 | S24: 59.6 | T24: 59.1 | V24: 58.4 | Z24: 59.5 | AA24: 60 | AC24: MANTENIMIENTO | AD24: =AB24-AA24 -> -60
A25: MACIEL THIAGO | B25: 63.8 | C25: 78.7 | D25: 77.8 | E25: 75.7 | F25: 76.2 | G25: 76.3 | H25: 75.7 | I25: 77.1 | J25: 77.2 | M25: 76.8 | N25: 76.7 | O25: 76.7 | R25: 76.4 | S25: 77 | T25: 75.6 | U25: 75.4 | V25: 76.5 | W25: 76.1 | X25: 76 | Y25: 75 | Z25: 76 | AA25: 75.8 | AB25: 76.2 | AC25: DESCENSO | AD25: =AB25-AA25 -> 0.4
A26: MEDINA NICOLAS | B26: 62.6 | C26: 61.9 | D26: 62.1 | E26: 62.8 | F26: 62.4 | G26: 62.3 | H26: 62.8 | I26: 63.5 | J26: 63.1 | K26: 63.7 | L26: 63.7 | M26: 64.1 | N26: 64.3 | O26: 65.2 | P26: 65.1 | Q26: 65.2 | R26: 66 | S26: 66.5 | T26: 65.9 | U26: 66.7 | V26: 67.3 | W26: 67.2 | X26: 67.4 | Y26: 66.8 | Z26: 67.9 | AA26: 67.5 | AB26: 68.2 | AC26: AUMENTO | AD26: =AB26-AA26 -> 0.7
A27: MONTIVERO LUCAS | B27: 75.4 | C27: 75.4 | D27: 74.9 | E27: 73.6 | F27: 74 | G27: 74.6 | H27: 74.2 | I27: 74.7 | L27: 75.9 | M27: 74.7 | N27: 75 | O27: 75.8 | P27: 76.8 | Q27: 76 | R27: 76.5 | S27: 77 | T27: 77.5 | U27: 78.3 | V27: 78.8 | W27: 79.1 | X27: 79.4 | Y27: 79.4 | Z27: 79.7 | AA27: 78.6 | AC27: MANTENIMIENTO | AD27: =AB27-AA27 -> -78.6
A28: MORENO THIAGO | B28: 71.2 | C28: 76.4 | D28: 75 | E28: 73.9 | F28: 74 | G28: 73.2 | H28: 74.3 | J28: 72.5 | K28: 73.2 | L28: 72.8 | M28: 74.6 | O28: 73.4 | P28: 74.4 | Q28: 73.1 | R28: 74 | S28: 75 | T28: 74 | U28: 74.2 | V28: 74.5 | W28: 74.7 | Z28: 73.6 | AA28: 76.1 | AB28: 73.9 | AC28: MANTENIMIENTO | AD28: =AB28-AA28 -> -2.2
A29: NUÑEZ TIZIANO | B29: 79.7 | C29: 80.4 | D29: 79.8 | E29: 80.4 | F29: 81.5 | G29: 81.6 | H29: 83.5 | J29: 80.8 | K29: 81.8 | L29: 81.7 | M29: 82.2 | O29: 82.8 | P29: 82.6 | Q29: 82.1 | R29: 82.4 | S29: 82 | T29: 82.3 | U29: 82.4 | V29: 82.7 | W29: 83.4 | X29: 82.9 | Z29: 82.7 | AA29: 82.3 | AB29: 82.4 | AC29: DESCENSO | AD29: =AB29-AA29 -> 0.1
A30: PANZUTO BENICIO | B30: 71.6 | C30: 70.8 | D30: 70.6 | E30: 71.6 | F30: 72.1 | G30: 73 | H30: 73 | I30: 74.4 | J30: 73.7 | K30: 73.8 | L30: 73.2 | M30: 73 | N30: 73.9 | O30: 73.6 | P30: 73.8 | Q30: 73.6 | R30: 75 | S30: 74.1 | T30: 75.1 | U30: 75.2 | V30: 74.8 | W30: 75.9 | X30: 75.2 | Y30: 74.7 | Z30: 73.5 | AA30: 74.4 | AB30: 73.5 | AC30: DESCENSO | AD30: =AB30-AA30 -> -0.9
A31: PAREDES TOMAS | B31: 62.4 | C31: 58.6 | D31: 60.3 | E31: 62 | F31: 61.6 | G31: 62.6 | H31: 63 | I31: 62.9 | M31: 62.9 | N31: 63 | O31: 63.2 | P31: 63 | Q31: 61.8 | R31: 62.1 | S31: 63 | T31: 64.6 | U31: 63.9 | V31: 63.9 | W31: 63.7 | X31: 63.5 | Z31: 62.5 | AA31: 64.4 | AB31: 63.5 | AC31: MANTENIMIENTO | AD31: =AB31-AA31 -> -0.9
A32: PENDAS VALENTIN | B32: 68.2 | C32: 67.5 | D32: 66.6 | E32: 67.1 | F32: 67.2 | H32: 67 | J32: 62.6 | K32: 68.5 | L32: 68.4 | N32: 68.7 | P32: 68.4 | Q32: 69 | R32: 69.9 | T32: 70.4 | U32: 69.7 | V32: 70.5 | W32: 70.2 | Z32: 71.1 | AA32: 71.1 | AB32: 71.7 | AD32: =AB32-AA32 -> 0.6
A33: PEREZ AGUSTIN | B33: 64.8 | C33: 64.5 | D33: 64.5 | E33: 65.4 | F33: 66 | G33: 65.6 | H33: 65.8 | I33: 66.4 | J33: 66.6 | K33: 67.3 | L33: 67.2 | M33: 67 | N33: 66.7 | O33: 66.9 | P33: 67 | Q33: 66.5 | R33: 67 | S33: 67.3 | T33: 67.7 | U33: 67.8 | V33: 67.7 | W33: 68.2 | X33: 67.6 | Y33: 68.7 | Z33: 68.8 | AA33: 68.7 | AB33: 68.2 | AC33: MANTENIMIENTO | AD33: =AB33-AA33 -> -0.5
A34: PEREZ THIAGO | B34: 62.3 | D34: 62.3 | E34: 62.9 | F34: 62.5 | G34: 62.1 | H34: 61.9 | I34: 62.9 | J34: 63.1 | K34: 63.2 | L34: 62.3 | M34: 62.6 | R34: 64.5 | S34: 64.8 | T34: 64 | V34: 63.4 | W34: 64.6 | Z34: 64.6 | AB34: 64.3 | AC34: AUMENTO | AD34: =AB34-AA34 -> 64.3
A35: RAGAZZI JOSUE | B35: 58.4 | C35: 61.9 | D35: 61.3 | E35: 61.4 | F35: 60.4 | G35: 60.2 | H35: 59.6 | I35: 59.9 | J35: 59.6 | K35: 60.1 | L35: 60.3 | M35: 59.8 | N35: 59.8 | O35: 60 | P35: 61 | Q35: 59.2 | R35: 58.9 | S35: 59.6 | T35: 60.2 | U35: 62.7 | V35: 62.3 | W35: 61.7 | X35: 62.3 | Y35: 62.8 | AA35: 61.7 | AB35: 62.5 | AC35: MANTENIMIENTO | AD35: =AB35-AA35 -> 0.8
A36: RODRIGUEZ ALEJANDRO | D36: 69.5 | E36: 69 | F36: 69.9 | G36: 68.9 | H36: 70.9 | I36: 71.8 | L36: 71.5 | M36: 72.5 | N36: 72.6 | O36: 73.5 | P36: 73.8 | Q36: 74 | R36: 74 | S36: 74.6 | T36: 74.3 | U36: 74.5 | V36: 75.6 | X36: 75.9 | Y36: 76.3 | Z36: 74.4 | AA36: 75.1 | AB36: 74.6 | AC36: DESCENSO | AD36: =AB36-AA36 -> -0.5
A37: SAN MARTIN LUCIANO | B37: 72.6 | C37: 76.7 | D37: 76.3 | E37: 75.6 | F37: 74.8 | G37: 74.6 | H37: 75.1 | I37: 74.2 | J37: 75.4 | M37: 76.3 | N37: 75.1 | O37: 76.5 | P37: 75.2 | Q37: 75.5 | R37: 75.7 | S37: 75 | T37: 75.4 | U37: 76.8 | V37: 76.2 | W37: 75.1 | X37: 75.9 | Y37: 75.8 | Z37: 74.2 | AC37: MANTENIMIENTO | AD37: =AB37-AA37 -> 0 | AF37: L
A38: SIGNORELLO SANTINO | B38: 66.7 | C38: 65.2 | D38: 65.3 | E38: 65.5 | F38: 65.4 | G38: 65.9 | H38: 66.4 | I38: 67.2 | J38: 67.2 | K38: 66.4 | L38: 67.4 | M38: 66.7 | N38: 66.9 | O38: 68.5 | P38: 68.4 | Q38: 68.4 | R38: 68.5 | S38: 68.1 | T38: 68.8 | U38: 68.6 | V38: 68.8 | W38: 69.5 | X38: 68.2 | Y38: 69.1 | Z38: 69.7 | AA38: 69.5 | AB38: 69.8 | AC38: AUMENTO | AD38: =AB38-AA38 -> 0.3
A39: SIMEONE RODRIGO | B39: 72.3 | C39: 71.5 | D39: 72.3 | E39: 70.7 | F39: 70.9 | G39: 72.2 | H39: 72.8 | I39: 72.2 | J39: 73.3 | K39: 73 | L39: 73.7 | M39: 72.7 | N39: 73.7 | O39: 73.7 | P39: 73.4 | Q39: 73.5 | R39: 73.2 | T39: 72.7 | U39: 73.9 | V39: 75.2 | W39: 74.8 | X39: 74.1 | Y39: 74.8 | Z39: 74 | AA39: 74 | AB39: 73 | AC39: DESCENSO | AD39: =AB39-AA39 -> -1
A40: VELAZQUEZ ROMAN | E40: 74.8 | F40: 73.4 | G40: 73.6 | H40: 75 | I40: 75.6 | J40: 76.3 | N40: 73.5 | O40: 73.6 | P40: 74.9 | Q40: 75.9 | R40: 74.7 | S40: 75.9 | T40: 77 | U40: 76.5 | V40: 77.5 | W40: 78.5 | X40: 78.1 | Y40: 78.6 | Z40: 77.5 | AA40: 78 | AB40: 77.6 | AC40: MANTENIMIENTO | AD40: =AB40-AA40 -> -0.4
...

Sheet 8VA (10)
A1: CAH - 8va div -25
A2: JUGADOR | B2: 2024 | C2: 45679 | D2: 45686 | E2: 45693 | F2: 45728 | G2: 45735 | H2: 45749 | I2: 45756 | J2: 45763 | K2: 45770 | L2: 45777 | M2: 45784 | N2: 45791 | O2: 45798 | P2: 45812 | Q2: 45819 | R2: 45826 | S2: 45849 | T2: 45861 | U2: 45868 | V2: 45875 | W2: 45882 | X2: 45903 | Y2: 45910 | Z2: 45917 | AA2: PAUTAS | AB2: DIFERENCIA sem | AC2: DIFERENCIA ANUAL
A3: ACOSTA GASTON | C3: 67.4 | D3: 67.7 | E3: 67.8 | F3: 67 | G3: 67.4 | H3: 67.8 | I3: 69.1 | J3: 68.6 | K3: 69.1 | L3: 68.9 | M3: 69.4 | N3: 69.5 | O3: 70 | P3: 69.5 | Q3: 69.2 | S3: 69 | T3: 69.6 | U3: 70.7 | V3: 69.9 | W3: 70.5 | X3: 70.6 | Y3: 70.8 | Z3: 70.5 | AA3: MANTENIMIENTO | AB3: =Z3-Y3 -> -0.3 | AC3: =X3-B3 -> 70.6
A4: ANDRADE BAUTISTA | B4: 71.3 | D4: 70.3 | E4: 69.8 | F4: 70.7 | G4: 71.6 | H4: 71.6 | I4: 72.5 | J4: 72.2 | K4: 72.3 | L4: 72 | M4: 72.6 | N4: 73 | O4: 73.6 | P4: 75 | Q4: 73.7 | R4: 73.8 | S4: 75.2 | T4: 75.6 | U4: 75.4 | V4: 74.9 | W4: 74.1 | X4: 74.6 | Y4: 74.1 | Z4: 73.5 | AA4: DESCENSO | AB4: =Z4-Y4 -> -0.6 | AC4: =X4-B4 -> 3.3
A5: ANGO LUCAS | B5: 66.3 | C5: 67 | D5: 65.9 | E5: 66.9 | F5: 67.3 | G5: 65.9 | H5: 66.9 | I5: 67.8 | J5: 67.1 | K5: 67.2 | L5: 66.2 | M5: 67 | N5: 66.2 | O5: 65.1 | P5: 67.2 | Q5: 67.2 | R5: 68 | S5: 68.4 | T5: 67.8 | U5: 68.5 | V5: 68.7 | W5: 67.8 | X5: 68.7 | Y5: 68.4 | AA5: DESCENSO | AB5: =Z5-Y5 -> -68.4 | AC5: =X5-B5 -> 2.4
A6: BENITEZ TIZIANO | B6: 59.8 | C6: 59.1 | F6: 59.9 | G6: 60.4 | I6: 60 | K6: 60 | L6: 59.2 | M6: 59.7 | O6: 58.2 | P6: 58.6 | Q6: 59.7 | R6: 59.7 | S6: 59.1 | V6: 59.6 | W6: 59.4 | X6: 60.9 | Y6: 59.6 | Z6: 59.6 | AA6: MANTENIMIENTO | AB6: =Z6-Y6 -> 0 | AC6: =X6-B6 -> 1.1
A7: BLANCO THIAGO | B7: 68.1 | C7: 66.7 | D7: 66.4 | E7: 67.6 | F7: 67.4 | G7: 66.9 | H7: 67.9 | I7: 67.3 | J7: 66.7 | K7: 67.9 | L7: 67.7 | M7: 68.4 | N7: 68 | O7: 68.5 | P7: 68.9 | Q7: 69 | R7: 69.4 | S7: 70.4 | T7: 70.2 | U7: 71.2 | V7: 70.9 | W7: 69.9 | X7: 68.8 | Y7: 69.6 | Z7: 68.5 | AA7: MANTENIMIENTO | AB7: =Z7-Y7 -> -1.1 | AC7: =X7-B7 -> 0.7
A8: BOGARIN HAZIEL | B8: 57.9 | C8: 57.2 | D8: 56.8 | E8: 56.7 | F8: 57.9 | G8: 57.3 | H8: 56.3 | I8: 56.6 | J8: 57.3 | K8: 56.7 | L8: 57.3 | M8: 57.4 | N8: 57.8 | O8: 58.3 | P8: 57.2 | Q8: 57.7 | R8: 57.6 | S8: 59.2 | T8: 59 | U8: 58.7 | V8: 59.3 | W8: 59.5 | X8: 59.9 | Y8: 59.6 | AA8: MANTENIMIENTO | AB8: =Z8-Y8 -> -59.6 | AC8: =X8-B8 -> 2
A9: CABALLERO BRUNO | B9: 73.2 | C9: 73.7 | E9: 73.9 | F9: 74.9 | G9: 73.8 | H9: 75.4 | I9: 74.3 | J9: 74.2 | K9: 74.9 | L9: 74.7 | M9: 73.7 | N9: 73.8 | O9: 73.9 | P9: 74 | Q9: 74.2 | R9: 75.6 | S9: 74.2 | T9: 76.5 | U9: 75.6 | V9: 76.9 | W9: 75.4 | X9: 76.8 | Y9: 77.2 | Z9: 76.2 | AA9: MANTENIMIENTO | AB9: =Z9-Y9 -> -1 | AC9: =X9-B9 -> 3.6
A10: CARRIZO SANTINO | B10: 72 | C10: 75 | D10: 75 | E10: 78.3 | F10: 78.2 | G10: 78.4 | H10: 77.9 | I10: 77.5 | J10: 77.3 | K10: 77.6 | L10: 78.7 | M10: 77.7 | N10: 78 | O10: 78.3 | P10: 79 | Q10: 79.2 | R10: 78.8 | S10: 79 | T10: 79.2 | U10: 80.4 | V10: 81 | W10: 80.6 | X10: 80 | Y10: 80.4 | Z10: 82.4 | AA10: MANTENIMIENTO | AB10: =Z10-Y10 -> 2 | AC10: =X10-B10 -> 8
A11: CORBANI JUAN | B11: 58.6 | C11: 61.3 | D11: 60.2 | F11: 61.4 | G11: 62.2 | H11: 62.4 | I11: 62.8 | J11: 62.5 | K11: 62.7 | L11: 62.5 | M11: 62.3 | N11: 62 | O11: 62.1 | P11: 62.4 | Q11: 62.1 | R11: 62.5 | S11: 63.3 | T11: 64.2 | U11: 63.9 | V11: 64.1 | W11: 65.4 | X11: 64.2 | Y11: 64.1 | Z11: 65.7 | AA11: MANTENIMIENTO | AB11: =Z11-Y11 -> 1.6 | AC11: =X11-B11 -> 5.6
A12: DE OLIVERA IGNACIO | B12: 56.2 | C12: 54.7 | D12: 54.3 | E12: 55.6 | F12: 55.5 | G12: 55.9 | H12: 56.2 | I12: 57 | J12: 56.9 | K12: 56.6 | L12: 56.6 | M12: 56.8 | N12: 57.4 | O12: 57 | P12: 58 | Q12: 57.2 | R12: 58 | S12: 58.6 | T12: 59.1 | U12: 58.7 | X12: 59.9 | Y12: 59.7 | Z12: 59.8 | AA12: MANTENIMIENTO | AB12: =Z12-Y12 -> 0.1 | AC12: =X12-B12 -> 3.7
A13: ENCINA ROMAN | B13: 69.8 | C13: 69.9 | D13: 69.7 | E13: 70.1 | F13: 70.1 | G13: 69.5 | H13: 70.1 | I13: 70.4 | J13: 69.8 | K13: 69.7 | L13: 70.2 | M13: 69.6 | N13: 69.5 | O13: 69.4 | P13: 71.2 | Q13: 71.1 | R13: 70.8 | S13: 71.9 | T13: 71.8 | U13: 71.7 | V13: 73.5 | W13: 72.4 | X13: 74 | Y13: 73.2 | Z13: 73.5 | AA13: MANTENIMIENTO | AB13: =Z13-Y13 -> 0.3 | AC13: =X13-B13 -> 4.2
A14: FERNANDEZ LAUTARO | B14: 59.4 | C14: 57.7 | D14: 57.2 | E14: 59 | F14: 59 | G14: 60.2 | H14: 59.7 | I14: 60.1 | J14: 59.5 | K14: 59.2 | L14: 60.6 | M14: 59.2 | N14: 60 | O14: 58.8 | P14: 58.9 | Q14: 58.8 | R14: 59.7 | S14: 59.4 | T14: 60.6 | U14: 60.3 | V14: 60.8 | W14: 61.1 | X14: 61.4 | Y14: 60.8 | Z14: 60.9 | AA14: MANTENIMIENTO | AB14: =Z14-Y14 -> 0.1 | AC14: =X14-B14 -> 2
A15: FRANCIOSA VITO | E15: 64 | F15: 63.4 | G15: 63.9 | H15: 64.7 | I15: 64.5 | K15: 64 | L15: 64.4 | N15: 63.8 | O15: 64.4 | P15: 63.9 | Q15: 64.6 | R15: 64.2 | S15: 65 | T15: 65.9 | U15: 63.1 | V15: 64 | W15: 65 | X15: 65.9 | Y15: 67.4 | Z15: 67.2 | AA15: MANTENIMIENTO | AB15: =Z15-Y15 -> -0.2 | AC15: =X15-B15 -> 65.9
A16: GARCIA RODRIGO | F16: 54.2 | G16: 57.6 | H16: 57.5 | I16: 54.2 | K16: 55.3 | M16: 55.2 | N16: 55 | O16: 54 | Q16: 55.2 | R16: 56.4 | S16: 56.9 | T16: 57.7 | U16: 57 | V16: 58 | W16: 57.3 | X16: 57.7 | Y16: 58 | Z16: 58.1 | AA16: MANTENIMIENTO | AB16: =Z16-Y16 -> 0.1 | AC16: =X16-B16 -> 57.7
A17: GENEZ LEANDRO | B17: 57.3 | C17: 55.8 | D17: 56.8 | E17: 56.9 | F17: 57.2 | G17: 57.6 | H17: 57.5 | I17: 57.9 | J17: 58.4 | K17: 58.6 | L17: 58.9 | M17: 58.9 | N17: 59 | O17: 58.9 | P17: 60 | Q17: 59.3 | R17: 59.7 | S17: 59.9 | T17: 59.3 | U17: 59.1 | V17: 59 | W17: 59.8 | X17: 58.4 | Y17: 59.5 | Z17: 58.1 | AA17: MANTENIMIENTO | AB17: =Z17-Y17 -> -1.4 | AC17: =X17-B17 -> 1.1
A18: GIGLIOTTI THIAGO | B18: 64.3 | C18: 65.9 | D18: 65 | F18: 65.8 | G18: 65.9 | H18: 65.6 | I18: 66.7 | J18: 67 | K18: 67.4 | L18: 67.5 | M18: 67.7 | N18: 68 | O18: 67.9 | P18: 67.2 | Q18: 67.5 | R18: 68 | S18: 67.5 | T18: 67.7 | U18: 68.6 | V18: 68.4 | W18: 69 | X18: 69.3 | Y18: 69 | Z18: 70.2 | AA18: MANTENIMIENTO | AB18: =Z18-Y18 -> 1.2 | AC18: =X18-B18 -> 5
A19: GRISOLIA THIAGO | B19: 64.2 | C19: 63.9 | D19: 64.4 | H19: 64.9 | I19: 65.7 | J19: 66.2 | K19: 66.2 | L19: 66.7 | M19: 66.6 | N19: 65.9 | O19: 66.6 | P19: 66.7 | Q19: 66 | R19: 66.8 | S19: 66.8 | T19: 67.4 | U19: 67.6 | V19: 68.3 | W19: 66.8 | Y19: 66.9 | Z19: 65.7 | AA19: MANTENIMIENTO | AB19: =Z19-Y19 -> -1.2 | AC19: =X19-B19 -> -64.2
A20: HERBELLA RAFAEL | B20: 51.9 | C20: 53.4 | D20: 52.2 | F20: 53 | G20: 52.9 | H20: 54.4 | I20: 55.4 | J20: 54.5 | K20: 55.1 | L20: 54.9 | M20: 55.6 | N20: 54.8 | O20: 54.9 | P20: 56 | Q20: 56.6 | R20: 56.3 | S20: 56.5 | T20: 55.1 | V20: 56.6 | W20: 56.8 | X20: 58.7 | Y20: 58.7 | Z20: 59.1 | AA20: MANTENIMIENTO | AB20: =Z20-Y20 -> 0.4 | AC20: =X20-B20 -> 6.8
A21: LAZARTE BENJAMIN | B21: 71.3 | C21: 70.8 | D21: 71.1 | E21: 70.2 | F21: 70.1 | G21: 69.8 | H21: 69.2 | K21: 71.1 | L21: 71.7 | M21: 70.2 | N21: 71.6 | O21: 72 | P21: 70.9 | Q21: 70.2 | R21: 70.4 | S21: 72.7 | T21: 72.3 | U21: 72.2 | V21: 72.6 | X21: 73.3 | Y21: 73.7 | Z21: 73.4 | AA21: MANTENIMIENTO | AB21: =Z21-Y21 -> -0.3 | AC21: =X21-B21 -> 2
A22: LEIVA JUAN | C22: 67.9 | D22: 68.8 | E22: 69.9 | F22: 68.7 | G22: 68.5 | H22: 70.2 | I22: 71.8 | J22: 71.9 | K22: 71.9 | L22: 73.1 | M22: 73.6 | N22: 70.9 | O22: 70.6 | P22: 71.6 | Q22: 71.5 | R22: 72.4 | S22: 72.4 | T22: 71.2 | U22: 71.8 | V22: 71.5 | W22: 72.2 | X22: 70.5 | Y22: 71.3 | Z22: 70.7 | AA22: MANTENIMIENTO | AB22: =Z22-Y22 -> -0.6 | AC22: =X22-B22 -> 70.5
A23: LEZCANO RAMIRO | B23: 68.2 | C23: 69.6 | D23: 68.4 | E23: 68.9 | F23: 69.5 | H23: 69 | J23: 69.2 | K23: 69.3 | L23: 69.3 | M23: 68.2 | N23: 68.5 | O23: 68.4 | P23: 69 | Q23: 69 | R23: 70 | S23: 69.2 | T23: 70.2 | U23: 71.3 | V23: 70.2 | W23: 70 | X23: 71.1 | Y23: 71 | Z23: 71.3 | AA23: DESCENSO | AB23: =Z23-Y23 -> 0.3 | AC23: =X23-B23 -> 2.9
A24: MANSO SANTIAGO | B24: 67.5 | C24: 67.3 | D24: 66 | E24: 66.6 | F24: 67.1 | G24: 66.2 | H24: 67.1 | I24: 67.6 | J24: 68.4 | K24: 68.7 | L24: 68.6 | M24: 68.9 | N24: 69 | O24: 68.9 | P24: 69.7 | Q24: 70 | R24: 69.9 | S24: 69.7 | T24: 71 | U24: 70.3 | V24: 70.1 | W24: 72.3 | X24: 70.8 | Y24: 71.7 | Z24: 72.5 | AA24: MANTENIMIENTO | AB24: =Z24-Y24 -> 0.8 | AC24: =X24-B24 -> 3.3
A25: MARTINEZ MARTIN | B25: 61.6 | C25: 60.6 | D25: 59.3 | E25: 61.6 | F25: 61.7 | G25: 64.1 | H25: 65.4 | J25: 62.8 | K25: 63.2 | L25: 64.3 | M25: 61.4 | N25: 61 | O25: 60.6 | P25: 62.8 | Q25: 61.8 | S25: 61.2 | T25: 60.7 | U25: 61.3 | V25: 61.7 | W25: 62 | X25: 64 | Y25: 63.3 | Z25: 64.3 | AA25: MANTENIMIENTO | AB25: =Z25-Y25 -> 1 | AC25: =X25-B25 -> 2.4
A26: MARTINEZ SANTIAGO | F26: 63.8 | G26: 65.1 | H26: 63.8 | I26: 62.1 | J26: 63.8 | K26: 65 | L26: 65.8 | M26: 64.4 | N26: 65 | O26: 65.2 | P26: 64.9 | Q26: 65.8 | R26: 65.5 | S26: 66.4 | T26: 66.7 | U26: 66.6 | V26: 66.7 | W26: 66.3 | X26: 66.5 | Y26: 66.9 | Z26: 66.8 | AA26: MANTENIMIENTO | AB26: =Z26-Y26 -> -0.1 | AC26: =X26-B26 -> 66.5
A27: MEDINA SANTIAGO | B27: 54.8 | C27: 54.8 | D27: 55.7 | E27: 63.8 | F27: 54.2 | H27: 55.4 | I27: 55.4 | J27: 55.2 | K27: 55.5 | L27: 54.9 | M27: 54.9 | N27: 55 | O27: 56 | P27: 55.4 | Q27: 55.6 | R27: 56.2 | S27: 55.6 | T27: 56.5 | U27: 56.1 | V27: 56.5 | W27: 56.3 | X27: 56.2 | Y27: 55.2 | Z27: 56.1 | AA27: MANTENIMIENTO | AB27: =Z27-Y27 -> 0.9 | AC27: =X27-B27 -> 1.4
A28: MORETTI BENAJMIN | B28: 64.5 | C28: 65.5 | D28: 64.9 | E28: 64 | F28: 64.6 | G28: 65.1 | H28: 64.3 | I28: 64.3 | J28: 63.8 | K28: 63.9 | L28: 64.7 | N28: 63.4 | O28: 64.7 | P28: 64.7 | Q28: 65 | R28: 65.7 | S28: 65.5 | T28: 66.2 | U28: 66.2 | V28: 66.5 | W28: 66.4 | X28: 67.3 | Y28: 68.1 | Z28: 67.5 | AA28: MANTENIMIENTO | AB28: =Z28-Y28 -> -0.6 | AC28: =X28-B28 -> 2.8
A29: PACHECO LUCIANO | B29: 60.9 | C29: 61.3 | D29: 61.5 | E29: 62.1 | F29: 61.3 | G29: 60.7 | H29: 62.5 | I29: 62.6 | J29: 61.1 | K29: 61.5 | L29: 61.2 | M29: 61.4 | N29: 61.6 | O29: 62.5 | P29: 62.3 | Q29: 62.2 | R29: 62.6 | S29: 62 | T29: 62.2 | U29: 62.8 | V29: 61.9 | W29: 61.7 | X29: 61.9 | Y29: 62.9 | Z29: 63.2 | AA29: MANTENIMIENTO | AB29: =Z29-Y29 -> 0.3 | AC29: =X29-B29 -> 1
A30: PEREZ RUIZ GALO | B30: 71.2 | D30: 72.9 | F30: 71.3 | G30: 72.4 | J30: 72.5 | K30: 73.3 | L30: 72.5 | M30: 72.6 | N30: 73.1 | P30: 73.2 | Q30: 73.5 | R30: 74.3 | S30: 75.3 | T30: 75.3 | U30: 74.6 | V30: 74.9 | W30: 75.6 | X30: 75.3 | Y30: 75.7 | Z30: 76 | AA30: DESCENSO | AB30: =Z30-Y30 -> 0.3 | AC30: =X30-B30 -> 4.1
A31: PUYOS RAMIRO | B31: 56.2 | C31: 55.6 | D31: 55.4 | E31: 55.6 | F31: 55.8 | G31: 55.8 | H31: 55.8 | J31: 55.8 | K31: 55.8 | L31: 55 | M31: 55.9 | N31: 56.2 | O31: 56.4 | P31: 56.8 | Q31: 55.8 | R31: 57.9 | S31: 56.9 | T31: 57 | U31: 57.4 | V31: 57.6 | W31: 56.8 | X31: 58.8 | Y31: 57.6 | Z31: 58.1 | AA31: MANTENIMIENTO | AB31: =Z31-Y31 -> 0.5 | AC31: =X31-B31 -> 2.6
A32: RINALDI LAUTARO | B32: 63.8 | C32: 64.2 | F32: 64.8 | G32: 65.6 | H32: 66.1 | I32: 66.1 | L32: 64.3 | O32: 65.1 | P32: 66.3 | R32: 67.5 | S32: 68.2 | T32: 68.4 | U32: 68.7 | V32: 68.5 | W32: 68.8 | X32: 67.8 | Y32: 68.2 | Z32: 68 | AA32: MANTENIMIENTO | AB32: =Z32-Y32 -> -0.2 | AC32: =X32-B32 -> 4
A33: RIQUELME LAUTARO | C33: 78.4 | D33: 77 | E33: 73.8 | F33: 74.6 | G33: 75.1 | H33: 74.3 | I33: 74.7 | J33: 74.4 | K33: 75 | L33: 73.5 | M33: 75.3 | N33: 74.5 | O33: 76.9 | P33: 76.2 | Q33: 75.5 | R33: 76.2 | S33: 77 | T33: 77.6 | U33: 77.4 | V33: 76.6 | W33: 77 | X33: 76.5 | Y33: 76.6 | Z33: 75.7 | AA33: DESCENSO | AB33: =Z33-Y33 -> -0.9 | AC33: =X33-B33 -> 76.5
A34: ROLDAN LAUTARO | C34: 74.6 | D34: 73.8 | E34: 72.9 | F34: 73.2 | G34: 72.4 | H34: 72.9 | I34: 7.5 | J34: 73.5 | K34: 73.9 | L34: 73.2 | M34: 73.2 | N34: 73.8 | P34: 73.9 | Q34: 73.9 | R34: 74.4 | S34: 74.2 | T34: 74.4 | U34: 74.1 | V34: 73.5 | W34: 73.7 | X34: 72.5 | Y34: 73 | Z34: 72.1 | AA34: DESCENSO | AB34: =Z34-Y34 -> -0.9 | AC34: =X34-B34 -> 72.5
A35: SANCHEZ RAMIRO | D35: 87.3 | E35: 85.8 | F35: 84.7 | G35: 85.9 | H35: 84.3 | J35: 85.6 | K35: 84.7 | L35: 85.7 | M35: 85.7 | N35: 87.3 | O35: 86.1 | P35: 85.9 | Q35: 87.5 | R35: 86.8 | S35: 87.5 | T35: 88.2 | U35: 89 | V35: 88.5 | W35: 87.3 | X35: 87.4 | Y35: 88 | Z35: 88.7 | AA35: DESCENSO | AB35: =Z35-Y35 -> 0.7 | AC35: =X35-B35 -> 87.4
A36: SOLABARRIETA LEONARDO | B36: 61.2 | C36: 63.8 | D36: 62.9 | E36: 62.7 | F36: 61.8 | G36: 61.3 | H36: 61.8 | I36: 62.3 | J36: 61.9 | K36: 62.3 | L36: 61.3 | M36: 62.5 | N36: 62.3 | O36: 63.3 | P36: 63.8 | Q36: 63.2 | R36: 63 | S36: 62.8 | T36: 64.2 | U36: 63.4 | V36: 64.3 | W36: 63.9 | X36: 64.5 | Y36: 64.8 | Z36: 65.5 | AA36: MANTENIMIENTO | AB36: =Z36-Y36 -> 0.7 | AC36: =X36-B36 -> 3.3
A37: TEJADA CRISTOPHER | B37: 59.8 | C37: 62 | D37: 61.1 | E37: 60.6 | F37: 60.9 | G37: 59.9 | H37: 58.9 | I37: 62.4 | J37: 61.6 | K37: 62.3 | L37: 61.1 | M37: 61.4 | N37: 62.5 | O37: 61.3 | P37: 61.8 | Q37: 61.8 | R37: 62.3 | S37: 62.5 | T37: 62.4 | U37: 62.1 | V37: 62.3 | W37: 62.8 | X37: 64 | Y37: 64 | Z37: 64 | AA37: MANTENIMIENTO | AB37: =Z37-Y37 -> 0 | AC37: =X37-B37 -> 4.2
A38: TOCNOLA TOBIAS | B38: 63.5 | C38: 63 | D38: 63.9 | E38: 64 | F38: 63.9 | G38: 63 | H38: 64.3 | I38: 65 | J38: 64.1 | K38: 64.5 | L38: 61.5 | N38: 62 | O38: 62.4 | P38: 61.7 | Q38: 62 | R38: 65.9 | S38: 64.9 | T38: 65.8 | U38: 66 | V38: 66.2 | W38: 65.4 | X38: 65.6 | Y38: 66.9 | Z38: 67.2 | AA38: MANTENIMIENTO | AB38: =Z38-Y38 -> 0.3 | AC38: =X38-B38 -> 2.1
A39: TORRES LUIS | B39: 88.2 | C39: 86 | D39: 85.2 | E39: 85.5 | F39: 83.6 | G39: 82.8 | H39: 85.7 | I39: 84.5 | J39: 83.8 | K39: 86.8 | L39: 86 | N39: 82.1 | O39: 84.9 | P39: 81.1 | Q39: 79.5 | S39: 77.1 | T39: 79.5 | U39: 80.8 | V39: 82.2 | W39: 81.2 | X39: 82.2 | Z39: 78.5 | AA39: MANTENIMIENTO | AB39: =Z39-Y39 -> 78.5 | AC39: =X39-B39 -> -6
A40: VASQUEZ EVER | B40: 54.2 | C40: 55.4 | D40: 54.1 | E40: 54.1 | F40: 53.9 | G40: 54.3 | H40: 54.2 | I40: 55.1 | K40: 54.5 | L40: 55 | M40: 56 | N40: 55.7 | O40: 56 | P40: 55.6 | Q40: 55.7 | R40: 55.6 | S40: 56 | T40: 55.6 | U40: 55.8 | V40: 56.2 | W40: 56.9 | X40: 56.3 | Y40: 56.7 | Z40: 56.6 | AA40: MANTENIMIENTO | AB40: =Z40-Y40 -> -0.1 | AC40: =X40-B40 -> 2.1
...

Sheet 9NA (11)
A1: CAH - 9na div -25
A2: JUGADOR | B2: 45679 | C2: 45686 | D2: 45728 | E2: 45735 | F2: 45749 | G2: 45756 | H2: 45763 | I2: 45770 | J2: 45777 | K2: 45784 | L2: 45791 | M2: 45798 | N2: 45812 | O2: 45819 | P2: 45826 | Q2: 45849 | R2: 45861 | S2: 45868 | T2: 45875 | U2: 45882 | V2: 45896 | W2: 45903 | X2: 45910 | Y2: 45917 | Z2: PAUTAS | AA2: DIFERENCIA sem | AB2: DIFERENCIA ANUAL
A3: AGUIRRE JONATHAN | B3: 80 | C3: 80.2 | D3: 79.7 | E3: 80.3 | F3: 80.2 | G3: 81 | H3: 81.5 | J3: 81.2 | K3: 81.2 | L3: 79.7 | M3: 79.7 | N3: 81.7 | O3: 81.2 | P3: 82.4 | Q3: 83 | R3: 83.2 | S3: 82.6 | T3: 82.6 | U3: 83 | V3: 82.9 | W3: 83.2 | X3: 82.9 | Y3: 82.6 | Z3: DESCENSO | AA3: =Y3-X3 -> -0.3 | AB3: =W3-B3 -> 3.2
A4: ALCARAZ JOEL | B4: 48.3 | C4: 48 | D4: 47.4 | E4: 47.8 | F4: 47.4 | G4: 47.8 | H4: 47.9 | I4: 48 | J4: 47.7 | K4: 48.2 | L4: 47.9 | M4: 48.4 | N4: 48.9 | O4: 49.6 | P4: 50.4 | Q4: 50.6 | R4: 50.5 | S4: 49.9 | T4: 50.1 | U4: 49.5 | V4: 49.7 | W4: 50.5 | X4: 50.2 | Y4: 50.9 | Z4: AUMENTO | AA4: =Y4-X4 -> 0.7 | AB4: =W4-B4 -> 2.2
A5: ARANDA GONZALO | B5: 55.2 | C5: 55 | D5: 55.7 | E5: 57.1 | F5: 56.7 | G5: 58.4 | H5: 57.6 | I5: 58.1 | J5: 57.2 | K5: 57.4 | L5: 57.7 | M5: 57.7 | N5: 58 | O5: 57.8 | P5: 59 | Q5: 60 | R5: 59.4 | S5: 59.2 | T5: 59.6 | U5: 60.2 | V5: 60.1 | W5: 60 | X5: 61.1 | Y5: 61.7 | Z5: MANTENIMIENTO | AA5: =Y5-X5 -> 0.6 | AB5: =W5-B5 -> 4.8
A6: BERNAL ELIAS | B6: 48.3 | D6: 50.6 | E6: 51.4 | F6: 51.3 | G6: 52.2 | I6: 53.3 | J6: 52.6 | K6: 51.9 | L6: 52.6 | M6: 53 | N6: 53.3 | O6: 53.9 | P6: 54 | Q6: 55 | R6: 54.4 | S6: 54.7 | T6: 54.8 | U6: 54.8 | V6: 55.3 | W6: 55.3 | X6: 55.3 | Y6: 55.4 | Z6: MANTENIMIENTO | AA6: =Y6-X6 -> 0.1 | AB6: =W6-B6 -> 7
A7: BRAMAJO BRAMAJO | B7: 55.9 | D7: 54.2 | E7: 54.6 | F7: 56.2 | G7: 55 | J7: 55.3 | K7: 54.8 | L7: 55.7 | M7: 56.5 | O7: 57.7 | P7: 57 | Q7: 56.1 | R7: 56.9 | S7: 56.6 | T7: 56.8 | U7: 57.5 | V7: 56.5 | W7: 57 | X7: 56.2 | Y7: 55 | Z7: AUMENTO | AA7: =Y7-X7 -> -1.2 | AB7: =W7-B7 -> 1.1
A8: CACEREZ RENZO | B8: 53.7 | C8: 54.5 | D8: 55.4 | E8: 54.7 | F8: 54.6 | G8: 54.9 | H8: 55 | I8: 55 | J8: 55.4 | K8: 55 | M8: 53.3 | N8: 54 | O8: 55.9 | P8: 55.3 | Q8: 56.6 | R8: 58 | S8: 58.1 | T8: 59 | U8: 58.7 | V8: 58.3 | W8: 59.4 | X8: 58.4 | Y8: 58.1 | Z8: MANTENIMIENTO | AA8: =Y8-X8 -> -0.3 | AB8: =W8-B8 -> 5.7
A9: CACEREZ TIZIANO | B9: 58.5 | C9: 57.7 | D9: 59.2 | E9: 60.4 | F9: 61.2 | G9: 61.4 | H9: 62.1 | I9: 61.8 | J9: 62 | K9: 62.9 | L9: 60.4 | M9: 60.9 | N9: 62.1 | O9: 61.3 | P9: 62.6 | Q9: 63.1 | R9: 63.9 | S9: 63.9 | T9: 63.2 | U9: 63.7 | V9: 63.5 | W9: 63.9 | X9: 64 | Y9: 64.2 | Z9: MANTENIMIENTO | AA9: =Y9-X9 -> 0.2 | AB9: =W9-B9 -> 5.4
A10: CARLUCCIO VALENTINO | B10: 51.4 | C10: 50.3 | D10: 51.4 | E10: 51.6 | F10: 51.8 | G10: 51.9 | H10: 52 | I10: 53 | J10: 52.9 | K10: 52.9 | L10: 53 | M10: 53.4 | N10: 53.3 | O10: 53.4 | P10: 53.7 | Q10: 53.1 | R10: 55 | S10: 54.2 | T10: 54.6 | U10: 54.3 | V10: 55.3 | W10: 54.9 | X10: 55.1 | Y10: 55.3 | Z10: MANTENIMIENTO | AA10: =Y10-X10 -> 0.2 | AB10: =W10-B10 -> 3.5
A11: CASAL AXEL | B11: 55 | E11: 56 | F11: 56.1 | H11: 55.9 | I11: 56.6 | K11: 56 | L11: 55.2 | M11: 54.8 | N11: 56 | O11: 56.9 | P11: 57.1 | Q11: 57.8 | R11: 58.3 | S11: 58.4 | T11: 57.6 | U11: 57.7 | V11: 58 | X11: 58.2 | Y11: 59 | Z11: MANTENIMIENTO | AA11: =Y11-X11 -> 0.8 | AB11: =W11-B11 -> -55
A12: CASCO DYLAN | B12: 58.5 | C12: 56.8 | D12: 58.5 | E12: 58.8 | F12: 59.2 | G12: 59.9 | H12: 59.5 | I12: 60.1 | J12: 60.6 | K12: 61 | L12: 60.7 | M12: 60.8 | N12: 61.4 | O12: 61.5 | P12: 61.8 | Q12: 62.9 | R12: 63.3 | S12: 63.3 | T12: 63.5 | U12: 63.6 | V12: 64.8 | W12: 64.1 | X12: 63.4 | Y12: 63.5 | Z12: DESCENSO | AA12: =Y12-X12 -> 0.1 | AB12: =W12-B12 -> 5.6
